Workbook

Sheet Q
A1: กิจการ | B1: รหัส | C1: หจก./บจก. | D1: รหัส | E1: ชื่อโรงงาน | F1: Type | G1: JAN | H1: FEB | I1: MAR | J1: APR | K1: MAY | L1: JUN | M1: JUL | N1: AUG | O1: SEP | P1: OCT | Q1: NOV
A2: 1-Metro | B2: FR109 | C2: บจก.เจเอ็นเจพี ซิเมนต์ | D2: 31ED | E2: หลวงแพ่ง | F2: NX | G2: 0.66 | H2: 0.46 | I2: 0.47 | J2: 0 | K2: 0.74 | L2: 0.62 | M2: 0.94 | N2: 0.57 | O2: 0 | P2: 0 | Q2: 0
A3: 1-Metro | B3: FR100 | C3: บจก.เอส.เอส.พี (072) คอนสตรัคชั่น | D3: 31EC | E3: คลองด่าน | F3: NX | G3: 1.66 | H3: 2.63 | I3: 1.57 | J3: 0.89 | K3: 1.61 | L3: 1.06 | M3: 1.14 | N3: 1.14 | O3: 0 | P3: 0 | Q3: 0
A4: 1-Metro | B4: FR187 | C4: หจก.เพาเวอร์ แลนด์ คอนกรีต | D4: 31EF | E4: นพวงศ์ | F4: NX | G4: 0 | H4: 0 | I4: 0 | J4: 0 | K4: 0.83 | L4: 0.92 | M4: 0.33 | N4: 0.17 | O4: 0 | P4: 0 | Q4: 0
A5: 1-Metro | B5: FR002 | C5: บจก.สหชัยธุรกิจก่อสร้าง 1993 | D5: FC139 | E5: คลอง 11 | F5: S | G5: 7.34 | H5: 0.89 | I5: 9.97 | J5: 8.22 | K5: 3.71 | L5: 0.69 | M5: 6.09 | N5: 1.52 | O5: 0 | P5: 0 | Q5: 0
A6: 2-East | B6: FR002 | C6: บจก.สหชัยธุรกิจก่อสร้าง 1993 | D6: FC095 | E6: มวกเหล็ก | F6: S | G6: 0.8 | H6: 1.14 | I6: 0.89 | J6: 0.85 | K6: 0.4 | L6: 0.74 | M6: 0.58 | N6: 0.49 | O6: 0 | P6: 0 | Q6: 0
A7: 2-East | B7: FR002 | C7: บจก.สหชัยธุรกิจก่อสร้าง 1993 | D7: FC046 | E7: วังม่วง | F7: S | G7: 1.38 | H7: 1.55 | I7: 0.73 | J7: 0.63 | K7: 0.78 | L7: 0.69 | M7: 0.51 | N7: 1.19 | O7: 0 | P7: 0 | Q7: 0
A8: 2-East | B8: FR002 | C8: บจก.สหชัยธุรกิจก่อสร้าง 1993 | D8: FC175 | E8: พัฒนานิคม | F8: S | G8: 1.08 | H8: 1.44 | I8: 0.34 | J8: 0.97 | K8: 0.75 | L8: 0.59 | M8: 0.34 | N8: 0.35 | O8: 0 | P8: 0 | Q8: 0
A9: 2-East | B9: FR002 | C9: บจก.สหชัยธุรกิจก่อสร้าง 1993 | D9: FC390 | E9: โคกสำโรง | F9: S | G9: 1.42 | H9: 1.4 | I9: 1.13 | J9: 1 | K9: 0.82 | L9: 1.18 | M9: 0.75 | N9: 0.75 | O9: 0 | P9: 0 | Q9: 0
A10: 2-East | B10: FR005 | C10: บจก.นิธิศพันธ์ | D10: FC013 | E10: ลำนารายณ์ | F10: S | G10: 0 | H10: -0.09 | I10: 0 | J10: 0 | K10: 0 | L10: 0 | M10: 0.92 | N10: 0.43 | O10: 0 | P10: 0 | Q10: 0
A11: 2-East | B11: FR003 | C11: บจก.ศุภภัณฑ์คอนกรีต | D11: FC111 | E11: ดาวเรือง 1 | F11: S | G11: 0.28 | H11: 0.31 | I11: 0.13 | J11: 0.74 | K11: 0.42 | L11: 0.53 | M11: 0.72 | N11: 0.58 | O11: 0 | P11: 0 | Q11: 0
A12: 2-East | B12: FR150 | C12: หจก.ดวงแสงทองคอนกรีต | D12: FC209 | E12: บ้านหมอ | F12: S | G12: 0.86 | H12: 1.09 | I12: 0.46 | J12: 0.69 | K12: 0.51 | L12: 0.19 | M12: 0.14 | N12: 0.25 | O12: 0 | P12: 0 | Q12: 0
A13: 2-East | B13: FR150 | C13: หจก.ดวงแสงทองคอนกรีต | D13: FC389 | E13: บ้านหมอ 2 | F13: S | G13: 0 | H13: 0 | I13: 0 | J13: 0 | K13: 0 | L13: 0 | M13: 0 | N13: 0 | O13: 0 | P13: 0 | Q13: 0
... A253: 6-South | B253: FR053 | C253: บจก.ไชยาคอนกรีต | D253: FC029 | E253: ไชยา | F253: S | G253: 0.94 | H253: 1.05 | I253: 0.92 | J253: 0.89 | K253: 0.85 | L253: 0.96 | M253: 1.08 | N253: 1.03 | O253: 0 | P253: 0 | Q253: 0
A254: 6-South | B254: FR159 | C254: บจก.ชุมพรไถ่เชียงคอนกรีต | D254: 3164 | E254: ปากน้ำชุมพร | F254: NX | G254: 1.68 | H254: 0.87 | I254: 0.68 | J254: 0.59 | K254: 0.75 | L254: 0.64 | M254: 0.76 | N254: 0.4 | O254: 0 | P254: 0 | Q254: 0
A255: 6-South | B255: FR159 | C255: บจก.ชุมพรไถ่เชียงคอนกรีต | D255: FC287 | E255: มาบอำมฤต | F255: S | G255: 1.24 | H255: 0.89 | I255: 0.64 | J255: 0.92 | K255: 1.33 | L255: 0.81 | M255: 0.64 | N255: 0.46 | O255: 0 | P255: 0 | Q255: 0
A256: 6-South | B256: FR211 | C256: บจก.คอนกรีตซีแพคระนอง | D256: FC282 | E256: ระนอง | F256: S | G256: 0.77 | H256: 0.59 | I256: 0.73 | J256: 0.56 | K256: 0.79 | L256: 1.36 | M256: 0.76 | N256: 0.47 | O256: 0 | P256: 0 | Q256: 0
A257: 6-South | B257: FR162 | C257: บจก.ผาหลวงคอนกรีต | D257: 3165 | E257: ผาหลวงคอนกรีต 1 | F257: NX | G257: 1.2 | H257: 0.86 | I257: 0.98 | J257: 1.04 | K257: 0.71 | L257: 1.02 | M257: 1.06 | N257: 1.59 | O257: 0 | P257: 0 | Q257: 0
A258: 6-South | B258: FR162 | C258: บจก.ผาหลวงคอนกรีต | D258: 3166 | E258: ผาหลวงคอนกรีต 2 | F258: NX | G258: 0 | H258: 0.64 | I258: 0 | J258: 0 | K258: 0 | L258: 0 | M258: 0 | N258: 0 | O258: 0 | P258: 0 | Q258: 0
A259: 6-South | B259: FR073 | C259: หจก.ลิ้มปิพงษ์ค้าวัสดุก่อสร้างและคอนกรีต | D259: FC115 | E259: เกาะพะงัน | F259: S | G259: 0 | H259: 1.2 | I259: 0 | J259: 0 | K259: 0 | L259: 1.29 | M259: 1.12 | N259: 1.15 | O259: 0 | P259: 0 | Q259: 0
A260: 6-South | B260: FR202 | C260: บจก.พุนพินมาตรฐานคอนกรีต | D260: 3168 | E260: หนองขรี | F260: NX | G260: 1.04 | H260: 2.02 | I260: 1.34 | J260: 1.62 | K260: 1.47 | L260: 0.84 | M260: 1.43 | N260: 0.99 | O260: 0 | P260: 0 | Q260: 0
A261: 6-South | B261: FR093 | C261: บจก.ปัญญามาตรฐานคอนกรีต | D261: FC253 | E261: นาสาร | F261: S | G261: 0.85 | H261: 0.79 | I261: 0.57 | J261: 0 | K261: 1.04 | L261: 1.08 | M261: 0.82 | N261: 0.81 | O261: 0 | P261: 0 | Q261: 0
A262: 6-South | B262: FR093 | C262: บจก.ปัญญามาตรฐานคอนกรีต | D262: FC129 | E262: ทุ่งใหญ่ | F262: S | G262: 0.97 | H262: 1.14 | I262: 1.69 | J262: 0.06 | K262: 1.03 | L262: 0.83 | M262: 0.76 | N262: 0.65 | O262: 0 | P262: 0 | Q262: 0
A263: 6-South | B263: FR093 | C263: บจก.ปัญญามาตรฐานคอนกรีต | D263: FC295 | E263: บางสวรรค์ 3 | F263: S | G263: 1.05 | H263: 0.99 | I263: 1.03 | J263: 0.71 | K263: 0.64 | L263: 1.11 | M263: 1.06 | N263: 0.97 | O263: 0 | P263: 0 | Q263: 0
A264: 6-South | B264: FR093 | C264: บจก.ปัญญามาตรฐานคอนกรีต | D264: FC356 | E264: นาสาร 2 | F264: S | G264: 0 | H264: 0 | I264: 0 | J264: 0 | K264: 0 | L264: 0 | M264: 0 | N264: 0 | O264: 0 | P264: 0 | Q264: 0
A265: 6-South | B265: FR093 | C265: บจก.ปัญญามาตรฐานคอนกรีต | D265: FC396 | E265: เวียงสระ | F265: S | G265: 0.77 | H265: 1.17 | I265: 0.9 | J265: 0.97 | K265: 1.16 | L265: 0.84 | M265: 0.73 | N265: 0.77 | O265: 0 | P265: 0 | Q265: 0
A266: 6-South | B266: FR055 | C266: หจก.ขนอมคอนกรีต 2000 | D266: FC006 | E266: ขนอม | F266: S | G266: 0.88 | H266: 0.72 | I266: 0.82 | J266: 1.03 | K266: 0.87 | L266: 0.96 | M266: 0.51 | N266: 1.02 | O266: 0 | P266: 0 | Q266: 0
... A291: 6-South | B291: FR097 | C291: หจก.วี.วี.เอ็มคอนกรีต | D291: FC413 | E291: เขาหลักโกลเด้นฮิลล์ | F291: S | G291: 0 | H291: 0 | I291: 0 | J291: 0 | K291: 0 | L291: 0 | M291: 0 | N291: 0 | O291: 0 | P291: 0 | Q291: 0

Sheet Q-Score
A1: กิจการ | B1: FCPLNO | C1: โรงงาน | D1: JAN | E1: FEB | F1: MAR | G1: APR | H1: MAY | I1: JUN | J1: JUL | K1: AUG | L1: SEP | M1: OCT | N1: NOV | O1: คะแนน | P1: Total | Q1: Dangerous | R1: Manual | S1: คะแนนรวม
A2: 1-Metro | B2: 31ED | C2: หลวงแพ่ง | G2: 0 | H2: 2.5 | I2: 1.25 | J2: 1.25 | K2: 1.25 | L2: 0 | M2: 0 | N2: 0 | O2: 6.25 | P2: =SUM(E2:N2) -> 6.25 | Q2: =SUMIF(Dangerous!$A:$A,'Q-Score'!$B2,Dangerous!$N:$N) -> 0 | R2: =SUMIF(Manual!$A:$A,'Q-Score'!$B2,Manual!$N:$N) -> 0 | S2: =SUM(P2:R2) -> 6.25
A3: 1-Metro | B3: 31EC | C3: คลองด่าน | G3: 1.25 | H3: 1.25 | I3: 1.25 | J3: 1.25 | K3: 1.25 | L3: 0 | M3: 0 | N3: 0 | O3: 6.25 | P3: =SUM(E3:N3) -> 6.25 | Q3: =SUMIF(Dangerous!$A:$A,'Q-Score'!$B3,Dangerous!$N:$N) -> 0 | R3: =SUMIF(Manual!$A:$A,'Q-Score'!$B3,Manual!$N:$N) -> 0 | S3: =SUM(P3:R3) -> 6.25
A4: 1-Metro | B4: 31EF | C4: นพวงศ์ | G4: 0 | H4: 1.25 | I4: 1.25 | J4: 0 | K4: 0 | L4: 0 | M4: 0 | N4: 0 | O4: 2.5 | P4: =SUM(E4:N4) -> 2.5 | Q4: =SUMIF(Dangerous!$A:$A,'Q-Score'!$B4,Dangerous!$N:$N) -> 0 | R4: =SUMIF(Manual!$A:$A,'Q-Score'!$B4,Manual!$N:$N) -> 0 | S4: =SUM(P4:R4) -> 2.5
A5: 1-Metro | B5: FC139 | C5: คลอง 11 | G5: 1.25 | H5: 1.25 | I5: 1.25 | J5: 1.25 | K5: 1.25 | L5: 0 | M5: 0 | N5: 0 | O5: 6.25 | P5: =SUM(E5:N5) -> 6.25 | Q5: =SUMIF(Dangerous!$A:$A,'Q-Score'!$B5,Dangerous!$N:$N) -> 0 | R5: =SUMIF(Manual!$A:$A,'Q-Score'!$B5,Manual!$N:$N) -> 0 | S5: =SUM(P5:R5) -> 6.25
A6: 2-East | B6: FC095 | C6: มวกเหล็ก | G6: 1.25 | H6: 0 | I6: 2.5 | J6: 1.25 | K6: 0 | L6: 0 | M6: 0 | N6: 0 | O6: 5 | P6: =SUM(E6:N6) -> 5 | Q6: =SUMIF(Dangerous!$A:$A,'Q-Score'!$B6,Dangerous!$N:$N) -> 0 | R6: =SUMIF(Manual!$A:$A,'Q-Score'!$B6,Manual!$N:$N) -> 0 | S6: =SUM(P6:R6) -> 5
A7: 2-East | B7: FC046 | C7: วังม่วง | G7: 1.25 | H7: 2.5 | I7: 1.25 | J7: 0 | K7: 1.25 | L7: 0 | M7: 0 | N7: 0 | O7: 6.25 | P7: =SUM(E7:N7) -> 6.25 | Q7: =SUMIF(Dangerous!$A:$A,'Q-Score'!$B7,Dangerous!$N:$N) -> 0 | R7: =SUMIF(Manual!$A:$A,'Q-Score'!$B7,Manual!$N:$N) -> 0 | S7: =SUM(P7:R7) -> 6.25
A8: 2-East | B8: FC175 | C8: พัฒนานิคม | G8: 1.25 | H8: 2.5 | I8: 1.25 | J8: 0 | K8: 0 | L8: 0 | M8: 0 | N8: 0 | O8: 5 | P8: =SUM(E8:N8) -> 5 | Q8: =SUMIF(Dangerous!$A:$A,'Q-Score'!$B8,Dangerous!$N:$N) -> 0 | R8: =SUMIF(Manual!$A:$A,'Q-Score'!$B8,Manual!$N:$N) -> 0 | S8: =SUM(P8:R8) -> 5
A9: 2-East | B9: FC390 | C9: โคกสำโรง | G9: 1.25 | H9: 1.25 | I9: 1.25 | J9: 2.5 | K9: 2.5 | L9: 0 | M9: 0 | N9: 0 | O9: 8.75 | P9: =SUM(E9:N9) -> 8.75 | Q9: =SUMIF(Dangerous!$A:$A,'Q-Score'!$B9,Dangerous!$N:$N) -> 0 | R9: =SUMIF(Manual!$A:$A,'Q-Score'!$B9,Manual!$N:$N) -> 0 | S9: =SUM(P9:R9) -> 8.75
A10: 2-East | B10: FC013 | C10: ลำนารายณ์ | G10: 0 | H10: 0 | I10: 0 | J10: 1.25 | K10: 0 | L10: 0 | M10: 0 | N10: 0 | O10: 1.25 | P10: =SUM(E10:N10) -> 1.25 | Q10: =SUMIF(Dangerous!$A:$A,'Q-Score'!$B10,Dangerous!$N:$N) -> 0 | R10: =SUMIF(Manual!$A:$A,'Q-Score'!$B10,Manual!$N:$N) -> 0 | S10: =SUM(P10:R10) -> 1.25
A11: 2-East | B11: FC111 | C11: ดาวเรือง 1 | G11: 2.5 | H11: 0 | I11: 0 | J11: 2.5 | K11: 1.25 | L11: 0 | M11: 0 | N11: 0 | O11: 6.25 | P11: =SUM(E11:N11) -> 6.25 | Q11: =SUMIF(Dangerous!$A:$A,'Q-Score'!$B11,Dangerous!$N:$N) -> 0 | R11: =SUMIF(Manual!$A:$A,'Q-Score'!$B11,Manual!$N:$N) -> 0 | S11: =SUM(P11:R11) -> 6.25
A12: 2-East | B12: FC209 | C12: บ้านหมอ | G12: 1.25 | H12: 0 | I12: 0 | J12: 0 | K12: 0 | L12: 0 | M12: 0 | N12: 0 | O12: 1.25 | P12: =SUM(E12:N12) -> 1.25 | Q12: =SUMIF(Dangerous!$A:$A,'Q-Score'!$B12,Dangerous!$N:$N) -> 0 | R12: =SUMIF(Manual!$A:$A,'Q-Score'!$B12,Manual!$N:$N) -> 0 | S12: =SUM(P12:R12) -> 1.25
A13: 2-East | B13: FC389 | C13: บ้านหมอ 2 | G13: 0 | H13: 0 | I13: 0 | J13: 0 | K13: 0 | L13: 0 | M13: 0 | N13: 0 | O13: 0 | P13: =SUM(E13:N13) -> 0 | Q13: =SUMIF(Dangerous!$A:$A,'Q-Score'!$B13,Dangerous!$N:$N) -> 0 | R13: =SUMIF(Manual!$A:$A,'Q-Score'!$B13,Manual!$N:$N) -> 0 | S13: =SUM(P13:R13) -> 0
... A254: 6-South | B254: FC029 | C254: ไชยา | G254: 1.25 | H254: 1.25 | I254: 1.25 | J254: 1.25 | K254: 1.25 | L254: 0 | M254: 0 | N254: 0 | O254: 6.25 | P254: =SUM(E254:N254) -> 6.25 | Q254: =SUMIF(Dangerous!$A:$A,'Q-Score'!$B254,Dangerous!$N:$N) -> 0 | R254: =SUMIF(Manual!$A:$A,'Q-Score'!$B254,Manual!$N:$N) -> 0 | S254: =SUM(P254:R254) -> 6.25
A255: 6-South | B255: 3164 | C255: ปากน้ำชุมพร | G255: 1.25 | H255: 2.5 | I255: 1.25 | J255: 2.5 | K255: 0 | L255: 0 | M255: 0 | N255: 0 | O255: 7.5 | P255: =SUM(E255:N255) -> 7.5 | Q255: =SUMIF(Dangerous!$A:$A,'Q-Score'!$B255,Dangerous!$N:$N) -> 0 | R255: =SUMIF(Manual!$A:$A,'Q-Score'!$B255,Manual!$N:$N) -> 0 | S255: =SUM(P255:R255) -> 7.5
A256: 6-South | B256: FC287 | C256: มาบอำมฤต | G256: 1.25 | H256: 1.25 | I256: 1.25 | J256: 1.25 | K256: 0 | L256: 0 | M256: 0 | N256: 0 | O256: 5 | P256: =SUM(E256:N256) -> 5 | Q256: =SUMIF(Dangerous!$A:$A,'Q-Score'!$B256,Dangerous!$N:$N) -> 0 | R256: =SUMIF(Manual!$A:$A,'Q-Score'!$B256,Manual!$N:$N) -> 0 | S256: =SUM(P256:R256) -> 5
A257: 6-South | B257: FC282 | C257: ระนอง | G257: 1.25 | H257: 2.5 | I257: 1.25 | J257: 2.5 | K257: 0 | L257: 0 | M257: 0 | N257: 0 | O257: 7.5 | P257: =SUM(E257:N257) -> 7.5 | Q257: =SUMIF(Dangerous!$A:$A,'Q-Score'!$B257,Dangerous!$N:$N) -> 0 | R257: =SUMIF(Manual!$A:$A,'Q-Score'!$B257,Manual!$N:$N) -> 0 | S257: =SUM(P257:R257) -> 7.5
A258: 6-South | B258: 3165 | C258: ผาหลวงคอนกรีต 1 | G258: 1.25 | H258: 2.5 | I258: 1.25 | J258: 1.25 | K258: 1.25 | L258: 0 | M258: 0 | N258: 0 | O258: 7.5 | P258: =SUM(E258:N258) -> 7.5 | Q258: =SUMIF(Dangerous!$A:$A,'Q-Score'!$B258,Dangerous!$N:$N) -> 0 | R258: =SUMIF(Manual!$A:$A,'Q-Score'!$B258,Manual!$N:$N) -> 0 | S258: =SUM(P258:R258) -> 7.5
A259: 6-South | B259: 3166 | C259: ผาหลวงคอนกรีต 2 | G259: 0 | H259: 0 | I259: 0 | J259: 0 | K259: 0 | L259: 0 | M259: 0 | N259: 0 | O259: 0 | P259: =SUM(E259:N259) -> 0 | Q259: =SUMIF(Dangerous!$A:$A,'Q-Score'!$B259,Dangerous!$N:$N) -> 0 | R259: =SUMIF(Manual!$A:$A,'Q-Score'!$B259,Manual!$N:$N) -> 0 | S259: =SUM(P259:R259) -> 0
A260: 6-South | B260: FC115 | C260: เกาะพะงัน | G260: 0 | H260: 0 | I260: 1.25 | J260: 1.25 | K260: 1.25 | L260: 0 | M260: 0 | N260: 0 | O260: 3.75 | P260: =SUM(E260:N260) -> 3.75 | Q260: =SUMIF(Dangerous!$A:$A,'Q-Score'!$B260,Dangerous!$N:$N) -> 0 | R260: =SUMIF(Manual!$A:$A,'Q-Score'!$B260,Manual!$N:$N) -> 0 | S260: =SUM(P260:R260) -> 3.75
A261: 6-South | B261: 3168 | C261: หนองขรี | G261: 1.25 | H261: 1.25 | I261: 1.25 | J261: 1.25 | K261: 1.25 | L261: 0 | M261: 0 | N261: 0 | O261: 6.25 | P261: =SUM(E261:N261) -> 6.25 | Q261: =SUMIF(Dangerous!$A:$A,'Q-Score'!$B261,Dangerous!$N:$N) -> 0 | R261: =SUMIF(Manual!$A:$A,'Q-Score'!$B261,Manual!$N:$N) -> 0 | S261: =SUM(P261:R261) -> 6.25
A262: 6-South | B262: FC253 | C262: นาสาร | G262: 0 | H262: 1.25 | I262: 1.25 | J262: 1.25 | K262: 1.25 | L262: 0 | M262: 0 | N262: 0 | O262: 5 | P262: =SUM(E262:N262) -> 5 | Q262: =SUMIF(Dangerous!$A:$A,'Q-Score'!$B262,Dangerous!$N:$N) -> 0 | R262: =SUMIF(Manual!$A:$A,'Q-Score'!$B262,Manual!$N:$N) -> 0 | S262: =SUM(P262:R262) -> 5
A263: 6-South | B263: FC129 | C263: ทุ่งใหญ่ | G263: 0 | H263: 1.25 | I263: 1.25 | J263: 2.5 | K263: 1.25 | L263: 0 | M263: 0 | N263: 0 | O263: 6.25 | P263: =SUM(E263:N263) -> 6.25 | Q263: =SUMIF(Dangerous!$A:$A,'Q-Score'!$B263,Dangerous!$N:$N) -> -2.5 | R263: =SUMIF(Manual!$A:$A,'Q-Score'!$B263,Manual!$N:$N) -> 0 | S263: =SUM(P263:R263) -> 3.75
A264: 6-South | B264: FC295 | C264: บางสวรรค์ 3 | G264: 2.5 | H264: 1.25 | I264: 1.25 | J264: 1.25 | K264: 1.25 | L264: 0 | M264: 0 | N264: 0 | O264: 7.5 | P264: =SUM(E264:N264) -> 7.5 | Q264: =SUMIF(Dangerous!$A:$A,'Q-Score'!$B264,Dangerous!$N:$N) -> 0 | R264: =SUMIF(Manual!$A:$A,'Q-Score'!$B264,Manual!$N:$N) -> 0 | S264: =SUM(P264:R264) -> 7.5
A265: 6-South | B265: FC356 | C265: นาสาร 2 | G265: 0 | H265: 0 | I265: 0 | J265: 0 | K265: 0 | L265: 0 | M265: 0 | N265: 0 | O265: 0 | P265: =SUM(E265:N265) -> 0 | Q265: =SUMIF(Dangerous!$A:$A,'Q-Score'!$B265,Dangerous!$N:$N) -> 0 | R265: =SUMIF(Manual!$A:$A,'Q-Score'!$B265,Manual!$N:$N) -> 0 | S265: =SUM(P265:R265) -> 0
A266: 6-South | B266: FC396 | C266: เวียงสระ | G266: 1.25 | H266: 1.25 | I266: 1.25 | J266: 2.5 | K266: 2.5 | L266: 0 | M266: 0 | N266: 0 | O266: 8.75 | P266: =SUM(E266:N266) -> 8.75 | Q266: =SUMIF(Dangerous!$A:$A,'Q-Score'!$B266,Dangerous!$N:$N) -> 0 | R266: =SUMIF(Manual!$A:$A,'Q-Score'!$B266,Manual!$N:$N) -> 0 | S266: =SUM(P266:R266) -> 8.75
A267: 6-South | B267: FC006 | C267: ขนอม | G267: 1.25 | H267: 1.25 | I267: 1.25 | J267: 0 | K267: 1.25 | L267: 0 | M267: 0 | N267: 0 | O267: 5 | P267: =SUM(E267:N267) -> 5 | Q267: =SUMIF(Dangerous!$A:$A,'Q-Score'!$B267,Dangerous!$N:$N) -> 0 | R267: =SUMIF(Manual!$A:$A,'Q-Score'!$B267,Manual!$N:$N) -> 0 | S267: =SUM(P267:R267) -> 5
... A292: 6-South | B292: FC413 | C292: เขาหลักโกลเด้นฮิลล์ | G292: 0 | H292: 0 | I292: 0 | J292: 0 | K292: 0 | L292: 0 | M292: 0 | N292: 0 | O292: 0 | P292: =SUM(E292:N292) -> 0 | Q292: =SUMIF(Dangerous!$A:$A,'Q-Score'!$B292,Dangerous!$N:$N) -> 0 | R292: =SUMIF(Manual!$A:$A,'Q-Score'!$B292,Manual!$N:$N) -> 0 | S292: =SUM(P292:R292) -> 0

Sheet Dangerous
A1: รหัส | B1: ชื่อโรงงาน | C1: JAN | D1: FEB | E1: MAR | F1: APR | G1: MAY | H1: JUN | I1: JUL | J1: AUG | K1: SEP | L1: OCT | M1: NOV | N1: Total
A2: FC139 | B2: คลอง 11 | N2: =SUM(C2:M2) -> 0
A3: 31EF | B3: นพวงศ์(N) | N3: =SUM(C3:M3) -> 0
A4: 31ED | B4: หลวงแพ่ง (N) | N4: =SUM(C4:M4) -> 0
A5: 31EC | B5: คลองด่าน (N) | N5: =SUM(C5:M5) -> 0
A6: FC105 | B6: นิคมพัฒนา | N6: =SUM(C6:M6) -> 0
A7: FC399 | B7: ตราด | N7: =SUM(C7:M7) -> 0
A8: FC068 | B8: บ้านอำเภอ 1 | N8: =SUM(C8:M8) -> 0
A9: FC117 | B9: บ้านอำเภอ 2 | N9: =SUM(C9:M9) -> 0
A10: FC169 | B10: มาบประชัน 1 | N10: =SUM(C10:M10) -> 0
A11: FC273 | B11: สัตหีบ 2 | N11: =SUM(C11:M11) -> 0
A12: FC043 | B12: เกาะช้าง | N12: =SUM(C12:M12) -> 0
A13: FC017 | B13: สอยดาว | N13: =SUM(C13:M13) -> 0
... A45: FC137 | B45: ห้วยมงคล | N45: =SUM(C45:M45) -> 0
A46: FC070 | B46: ท่ามะกา | F46: -2.5 | N46: =SUM(C46:M46) -> -2.5
A47: FC254 | B47: พนมทวน | I47: -2.5 | J47: -2.5 | N47: =SUM(C47:M47) -> -5
A48: FC369 | B48: FC กาญจนบุรี 2 | N48: =SUM(C48:M48) -> 0
A49: FC397 | B49: ท่าม่วง | N49: =SUM(C49:M49) -> 0
A50: FC158 | B50: แก่งกระจาน | N50: =SUM(C50:M50) -> 0
A51: FC069 | B51: จอมบึง | N51: =SUM(C51:M51) -> 0
A52: FC236 | B52: ทับสะแก | H52: -2.5 | J52: -2.5 | N52: =SUM(C52:M52) -> -5
A53: FC009 | B53: ประจวบคีรีขันธ์ | N53: =SUM(C53:M53) -> 0
A54: FC035 | B54: บางสะพาน | N54: =SUM(C54:M54) -> 0
A55: FC176 | B55: บางตะเคียน | N55: =SUM(C55:M55) -> 0
A56: FC201 | B56: ศรีประจันต์ | N56: =SUM(C56:M56) -> 0
A57: FC214 | B57: ดอนเจดีย์ | N57: =SUM(C57:M57) -> 0
A58: FC248 | B58: สองพี่น้อง | N58: =SUM(C58:M58) -> 0
A59: FC299 | B59: สองพี่น้อง 2 | N59: =SUM(C59:M59) -> 0
A60: FC092 | B60: อู่ทอง | N60: =SUM(C60:M60) -> 0
A61: FC142 | B61: บางปลาม้า | N61: =SUM(C61:M61) -> 0
A62: FC249 | B62: ด่านช้าง 2 | N62: =SUM(C62:M62) -> 0
A63: FC138 | B63: หันตรา | G63: -2.5 | N63: =SUM(C63:M63) -> -2.5
A64: FC197 | B64: สรรคบุรี | N64: =SUM(C64:M64) -> 0
A65: FC094 | B65: บางระกำ | N65: =SUM(C65:M65) -> 0
A66: FC250 | B66: ลานกระบือ | N66: =SUM(C66:M66) -> 0
A67: FC148 | B67: พรานกระต่าย | N67: =SUM(C67:M67) -> 0
A68: FC208 | B68: พรหมพิราม | N68: =SUM(C68:M68) -> 0
A69: FC207 | B69: กงไกรลาศ | N69: =SUM(C69:M69) -> 0
A70: FC373 | B70: เนินมะปราง (Type M) | N70: =SUM(C70:M70) -> 0
A71: FC240 | B71: ทรัพย์ไพรวัลย์ | N71: =SUM(C71:M71) -> 0
...

Sheet Manual
A1: รหัส | B1: ชื่อโรงงาน | C1: JAN | D1: FEB | E1: MAR | F1: APR | G1: MAY | H1: JUN | I1: JUL | J1: AUG | K1: SEP | L1: OCT | M1: NOV | N1: Total
A2: FC139 | B2: คลอง 11 | N2: =SUM(C2:M2) -> 0
A3: 31EF | B3: นพวงศ์(N) | N3: =SUM(C3:M3) -> 0
A4: 31ED | B4: หลวงแพ่ง (N) | N4: =SUM(C4:M4) -> 0
A5: 31EC | B5: คลองด่าน (N) | N5: =SUM(C5:M5) -> 0
A6: FC105 | B6: นิคมพัฒนา | N6: =SUM(C6:M6) -> 0
A7: FC399 | B7: ตราด | N7: =SUM(C7:M7) -> 0
A8: FC068 | B8: บ้านอำเภอ 1 | N8: =SUM(C8:M8) -> 0
A9: FC117 | B9: บ้านอำเภอ 2 | N9: =SUM(C9:M9) -> 0
A10: FC169 | B10: มาบประชัน 1 | N10: =SUM(C10:M10) -> 0
A11: FC273 | B11: สัตหีบ 2 | N11: =SUM(C11:M11) -> 0
A12: FC043 | B12: เกาะช้าง | N12: =SUM(C12:M12) -> 0
A13: FC017 | B13: สอยดาว | N13: =SUM(C13:M13) -> 0
... A286: FC115 | B286: เกาะพงัน | N286: =SUM(C286:M286) -> 0
