Workbook

Sheet รายชื่อจบส.
A1: รหัสโรงงาน | B1: REGION | C1: บจก./หจก. | D1: ลำดับ | E1: รหัส | F1: ชื่อภาษาไทย | G1: นามสกุลภาษาไทย | H1: โรงงาน | I1: Status | J1: TEAM | K1: ชื่อ-นามสกุล | L1: เดือนที่อบรม
A2: 13O3 | B2: 2-East | C2: บจ.บูรพาคอนกรีต แอนด์ คอนสตรัคชั่น | D2: 1 | E2: 160004 | F2: เดชา | G2: ชลชีพ | H2: บูรพา ท่าหลวง (FC Type X) | I2: ยังไม่อบรม | J2: สาโรจน์ | K2: เดชาชลชีพ | L2: ยังไม่อบรม
A3: 13O3 | B3: 2-East | C3: บจ.บูรพาคอนกรีต แอนด์ คอนสตรัคชั่น | D3: 1 | E3: 160006 | F3: สมบัติ | G3: พุทธพฤกษ์ | H3: บูรพา ท่าหลวง (FC Type X) | I3: ยังไม่อบรม | J3: สาโรจน์ | K3: สมบัติพุทธพฤกษ์ | L3: ยังไม่อบรม
A4: 13O3 | B4: 2-East | C4: บจ.บูรพาคอนกรีต แอนด์ คอนสตรัคชั่น | D4: 1 | E4: 160009 | F4: บรรจบ | G4: วิมาลา | H4: บูรพา ท่าหลวง (FC Type X) | I4: ยังไม่อบรม | J4: สาโรจน์ | K4: บรรจบวิมาลา | L4: ยังไม่อบรม
A5: 13O3 | B5: 2-East | C5: บจ.บูรพาคอนกรีต แอนด์ คอนสตรัคชั่น | D5: 1 | E5: 160010 | F5: จรูญ | G5: บุญอภัย | H5: บูรพา ท่าหลวง (FC Type X) | I5: ยังไม่อบรม | J5: สาโรจน์ | K5: จรูญบุญอภัย | L5: ยังไม่อบรม
A6: 13O3 | B6: 2-East | C6: บจ.บูรพาคอนกรีต แอนด์ คอนสตรัคชั่น | D6: 1 | E6: 160011 | F6: ฤกษ์ชัย | G6: เที่ยงธรรม | H6: บูรพา ท่าหลวง (FC Type X) | I6: ยังไม่อบรม | J6: สาโรจน์ | K6: ฤกษ์ชัยเที่ยงธรรม | L6: ยังไม่อบรม
A7: 13O3 | B7: 2-East | C7: บจ.บูรพาคอนกรีต แอนด์ คอนสตรัคชั่น | D7: 1 | E7: 160013 | F7: ทองปาน | G7: สองอุทธา | H7: บูรพา ท่าหลวง (FC Type X) | I7: ยังไม่อบรม | J7: สาโรจน์ | K7: ทองปานสองอุทธา | L7: ยังไม่อบรม
A8: 13O3 | B8: 2-East | C8: บจ.บูรพาคอนกรีต แอนด์ คอนสตรัคชั่น | D8: 1 | E8: 160020 | F8: นรากร | G8: เหลืองวิเศษ | H8: บูรพา ท่าหลวง (FC Type X) | I8: ยังไม่อบรม | J8: สาโรจน์ | K8: นรากรเหลืองวิเศษ | L8: ยังไม่อบรม
A9: 13O3 | B9: 2-East | C9: บจ.บูรพาคอนกรีต แอนด์ คอนสตรัคชั่น | D9: 1 | E9: 160025 | F9: วิชา | G9: หลอดทอง | H9: บูรพา ท่าหลวง (FC Type X) | I9: ยังไม่อบรม | J9: สาโรจน์ | K9: วิชาหลอดทอง | L9: ยังไม่อบรม
A10: 13O4 | B10: 2-East | C10: บจ. ส.ชัยโย ขนส่ง | D10: 1 | E10: 860008 | F10: พรประสิทธิ์ | G10: ศรีบุญเรือง | H10: วี.เอส.คอนกรีต(Type X) | I10: ผ่าน | J10: อดิเรก | K10: พรประสิทธิ์ศรีบุญเรือง | L10: 9
A11: 13O4 | B11: 2-East | C11: บจ.เสริมสินไพบูลย์ | D11: 1 | E11: 1R0028 | F11: ริน | G11: รักษา | H11: วี.เอส.คอนกรีต(Type X) | I11: ผ่าน | J11: อดิเรก | K11: รินรักษา | L11: 8
A12: 13O4 | B12: 2-East | C12: บจ.เสริมสินไพบูลย์ | D12: 1 | E12: 1R0052 | F12: รังสรรค์ | G12: จันทนะมูลตรี | H12: วี.เอส.คอนกรีต(Type X) | I12: ผ่าน | J12: อดิเรก | K12: รังสรรค์จันทนะมูลตรี | L12: 5
A13: 13O4 | B13: 2-East | C13: บจ.เสริมสินไพบูลย์ | D13: 1 | E13: 1R0090 | F13: สิริพงศ์ | G13: บุตรดี | H13: วี.เอส.คอนกรีต(Type X) | I13: ผ่าน | J13: อดิเรก | K13: สิริพงศ์บุตรดี | L13: 2
A14: 13O4 | B14: 2-East | C14: บจ.เสริมสินไพบูลย์ | D14: 1 | E14: 1R0132 | F14: สุขชัย | G14: โพธารินทร์ | H14: วี.เอส.คอนกรีต(Type X) | I14: ผ่าน | J14: อดิเรก | K14: สุขชัยโพธารินทร์ | L14: 8
A15: 13O4 | B15: 2-East | C15: บจ.แสงทองขนส่งภาคใต้ | D15: 1 | E15: OA0297 | F15: จักรี | G15: กันชม | H15: วี.เอส.คอนกรีต(Type X) | I15: ยังไม่อบรม | J15: อดิเรก | K15: จักรีกันชม | L15: ยังไม่อบรม
A16: 13O4 | B16: 2-East | C16: บจ.แสงทองขนส่งภาคใต้ | D16: 1 | E16: OA0299 | F16: สรุชัย | G16: พรหมโชติ | H16: วี.เอส.คอนกรีต(Type X) | I16: ยังไม่อบรม | J16: อดิเรก | K16: สรุชัยพรหมโชติ | L16: ยังไม่อบรม
A17: 13O4 | B17: 2-East | C17: บจ.แสงทองขนส่งภาคใต้ | D17: 1 | E17: OA1310 | F17: ประกาษิต | G17: สร้อยเพชร | H17: วี.เอส.คอนกรีต(Type X) | I17: ผ่าน | J17: อดิเรก | K17: ประกาษิตสร้อยเพชร | L17: 8
A18: 13O4 | B18: 2-East | C18: บจ.รุ่งภัทศุ | D18: 1 | E18: 890027 | F18: มนตรี | G18: ใจบุญเหลือ | H18: วี.เอส.คอนกรีต(Type X) | I18: ผ่าน | J18: อดิเรก | K18: มนตรีใจบุญเหลือ | L18: 6
A19: 13O4 | B19: 2-East | C19: หจก.วี.เอส.อินดัสเตรียล ซัพพลาย | D19: 1 | E19: 120002 | F19: ขจรศักดิ์ | G19: ทัพสุเทพ | H19: วี.เอส.คอนกรีต(Type X) | I19: ผ่าน | J19: อดิเรก | K19: ขจรศักดิ์ทัพสุเทพ | L19: 8
A20: 13O4 | B20: 2-East | C20: หจก.วี.เอส.อินดัสเตรียล ซัพพลาย | D20: 1 | E20: 120008 | F20: อนุชัย | G20: แม่นปืน | H20: วี.เอส.คอนกรีต(Type X) | I20: ไม่ผ่าน | J20: อดิเรก | K20: อนุชัยแม่นปืน | L20: 8
A21: 13O4 | B21: 2-East | C21: หจก.วี.เอส.อินดัสเตรียล ซัพพลาย | D21: 1 | E21: 120010 | F21: วิโรจ | G21: ทองพิมพ์ | H21: วี.เอส.คอนกรีต(Type X) | I21: ผ่าน | J21: อดิเรก | K21: วิโรจทองพิมพ์ | L21: 8
A22: 13O4 | B22: 2-East | C22: หจก.วี.เอส.อินดัสเตรียล ซัพพลาย | D22: 1 | E22: 120011 | F22: วัชระ | G22: นักปรัชญ์ | H22: วี.เอส.คอนกรีต(Type X) | I22: ผ่าน | J22: อดิเรก | K22: วัชระนักปรัชญ์ | L22: 9
A23: 13O4 | B23: 2-East | C23: หจก.วี.เอส.อินดัสเตรียล ซัพพลาย | D23: 1 | E23: 120013 | F23: สำอาง | G23: ประไพ | H23: วี.เอส.คอนกรีต(Type X) | I23: ไม่ผ่าน | J23: อดิเรก | K23: สำอางประไพ | L23: 8
A24: 13O4 | B24: 2-East | C24: หจก.วี.เอส.อินดัสเตรียล ซัพพลาย | D24: 1 | E24: 120016 | F24: ชวาลภพ | G24: เกลี้ยงพรมไข | H24: วี.เอส.คอนกรีต(Type X) | I24: ผ่าน | J24: อดิเรก | K24: ชวาลภพเกลี้ยงพรมไข | L24: 8
A25: 13O4 | B25: 2-East | C25: หจก.วี.เอส.อินดัสเตรียล ซัพพลาย | D25: 1 | E25: 120017 | F25: สุขพงค์ | G25: พิทักษ์ | H25: วี.เอส.คอนกรีต(Type X) | I25: ผ่าน | J25: อดิเรก | K25: สุขพงค์พิทักษ์ | L25: 8
A26: 13O4 | B26: 2-East | C26: หจก.วี.เอส.อินดัสเตรียล ซัพพลาย | D26: 1 | E26: 120020 | F26: วิชาญ | G26: วงษ์บาท | H26: วี.เอส.คอนกรีต(Type X) | I26: ไม่ผ่าน | J26: อดิเรก | K26: วิชาญวงษ์บาท | L26: 8
A27: 13O4 | B27: 2-East | C27: หจก.วี.เอส.อินดัสเตรียล ซัพพลาย | D27: 1 | E27: 120021 | F27: ทินกร | G27: นาหัวนิล | H27: วี.เอส.คอนกรีต(Type X) | I27: ไม่ผ่าน | J27: อดิเรก | K27: ทินกรนาหัวนิล | L27: 8
A28: 13O4 | B28: 2-East | C28: หจก.วี.เอส.อินดัสเตรียล ซัพพลาย | D28: 1 | E28: 120024 | F28: สมพงษ์ | G28: เลยา | H28: วี.เอส.คอนกรีต(Type X) | I28: ผ่าน | J28: อดิเรก | K28: สมพงษ์เลยา | L28: 9
A29: 13O4 | B29: 2-East | C29: หจก.วี.เอส.อินดัสเตรียล ซัพพลาย | D29: 1 | E29: 120026 | F29: วงศกร | G29: เกษอุบล | H29: วี.เอส.คอนกรีต(Type X) | I29: ยังไม่อบรม | J29: อดิเรก | K29: วงศกรเกษอุบล | L29: ยังไม่อบรม
A30: 13O4 | B30: 2-East | C30: หจก.วี.เอส.อินดัสเตรียล ซัพพลาย | D30: 1 | E30: 120027 | F30: อาทิตย์ | G30: เรืองบรรเทิง | H30: วี.เอส.คอนกรีต(Type X) | I30: ผ่าน | J30: อดิเรก | K30: อาทิตย์เรืองบรรเทิง | L30: 2
A31: 13O4 | B31: 2-East | C31: หจก.วี.เอส.อินดัสเตรียล ซัพพลาย | D31: 1 | E31: 120028 | F31: ประวิทย์ | G31: ศรีฉายา | H31: วี.เอส.คอนกรีต(Type X) | I31: ผ่าน | J31: อดิเรก | K31: ประวิทย์ศรีฉายา | L31: 8
A32: 13O4 | B32: 2-East | C32: หจก.วี.เอส.อินดัสเตรียล ซัพพลาย | D32: 1 | E32: 120029 | F32: สุรชัย | G32: ซ่ำอยู่ | H32: วี.เอส.คอนกรีต(Type X) | I32: ผ่าน | J32: อดิเรก | K32: สุรชัยซ่ำอยู่ | L32: 8
A33: 13O4 | B33: 2-East | C33: หจก.วี.เอส.อินดัสเตรียล ซัพพลาย | D33: 1 | E33: 120031 | F33: สุริยะ | G33: วิลัยกรวด | H33: วี.เอส.คอนกรีต(Type X) | I33: ผ่าน | J33: อดิเรก | K33: สุริยะวิลัยกรวด | L33: 8
A34: 13O4 | B34: 2-East | C34: หจก.วี.เอส.อินดัสเตรียล ซัพพลาย | D34: 1 | E34: 420003 | F34: อดุลย์ | G34: กำไรเงิน | H34: วี.เอส.คอนกรีต(Type X) | I34: ผ่าน | J34: อดิเรก | K34: อดุลย์กำไรเงิน | L34: 8
A35: 13O4 | B35: 2-East | C35: หจก.วี.เอส.อินดัสเตรียล ซัพพลาย | D35: 1 | E35: 420004 | F35: ศักดิ์ณรงค์ | G35: โกษาจันทร์ | H35: วี.เอส.คอนกรีต(Type X) | I35: ผ่าน | J35: อดิเรก | K35: ศักดิ์ณรงค์โกษาจันทร์ | L35: 8
A36: 13O5 | B36: 2-East | C36: East LOGISTICS | D36: 1 | E36: 150021 | F36: นิคม | G36: อุตรัตน์ | H36: ซิโนมา Type X | I36: ยังไม่อบรม | J36: อภิชะยา | K36: นิคมอุตรัตน์ | L36: ยังไม่อบรม
A37: 13O5 | B37: 2-East | C37: East LOGISTICS | D37: 1 | E37: 150028 | F37: บุญเลิศ | G37: เสาร์ปัญญา | H37: ซิโนมา Type X | I37: ยังไม่อบรม | J37: อภิชะยา | K37: บุญเลิศเสาร์ปัญญา | L37: ยังไม่อบรม
A38: 13O5 | B38: 2-East | C38: East LOGISTICS | D38: 1 | E38: 150026 | F38: ไพฑูรย์ | G38: โพธิ์สำโรง | H38: ซิโนมา Type X | I38: ยังไม่อบรม | J38: อภิชะยา | K38: ไพฑูรย์โพธิ์สำโรง | L38: ยังไม่อบรม
A39: 13O5 | B39: 2-East | C39: East LOGISTICS | D39: 1 | E39: 150025 | F39: สังวรณ์ | G39: ชีพนุรัตน์ | H39: ซิโนมา Type X | I39: ยังไม่อบรม | J39: อภิชะยา | K39: สังวรณ์ชีพนุรัตน์ | L39: ยังไม่อบรม
A40: 13O5 | B40: 2-East | C40: East LOGISTICS | D40: 1 | E40: 150023 | F40: วิโรจน์ | G40: ทองรักษ์ | H40: ซิโนมา Type X | I40: ยังไม่อบรม | J40: อภิชะยา | K40: วิโรจน์ทองรักษ์ | L40: ยังไม่อบรม
...

Sheet จบส.-Score
A1: กิจการ | B1: FCPLNO | C1: โรงงาน | D1: จำนวน จบส. | E1: อบรมแล้ว | F1: ยังไม่อบรม | G1: คะแนน | H1: Month
A2: 4-North | B2: FC045 | C2: ขาณุวรลักษบุรี | D2: =COUNTIF(รายชื่อจบส.!$A:$A,$B2) -> 2 | E2: =COUNTIFS(รายชื่อจบส.!$A:$A,$B2,รายชื่อจบส.!$I:$I,"ผ่าน") -> 0 | F2: =E2-D2 -> -2 | G2: =IF(AND(D2>0,F2=0,H2<=7),3,IF(AND(D2>0,F2=0,H2<=11),2,IF(AND(D2>0,F2=0,H2=12),1,0))) -> 0 | H2: =_xlfn.MAXIFS(รายชื่อจบส.!$L:$L,รายชื่อจบส.!$A:$A,$B2) -> 0
A3: 4-North | B3: FC067 | C3: ท่าตะโก | D3: =COUNTIF(รายชื่อจบส.!$A:$A,$B3) -> 4 | E3: =COUNTIFS(รายชื่อจบส.!$A:$A,$B3,รายชื่อจบส.!$I:$I,"ผ่าน") -> 2 | F3: =E3-D3 -> -2 | G3: =IF(AND(D3>0,F3=0,H3<=7),3,IF(AND(D3>0,F3=0,H3<=11),2,IF(AND(D3>0,F3=0,H3=12),1,0))) -> 0 | H3: =_xlfn.MAXIFS(รายชื่อจบส.!$L:$L,รายชื่อจบส.!$A:$A,$B3) -> 7
A4: 4-North | B4: FC289 | C4: คลองขลุง 2 | D4: =COUNTIF(รายชื่อจบส.!$A:$A,$B4) -> 2 | E4: =COUNTIFS(รายชื่อจบส.!$A:$A,$B4,รายชื่อจบส.!$I:$I,"ผ่าน") -> 1 | F4: =E4-D4 -> -1 | G4: =IF(AND(D4>0,F4=0,H4<=7),3,IF(AND(D4>0,F4=0,H4<=11),2,IF(AND(D4>0,F4=0,H4=12),1,0))) -> 0 | H4: =_xlfn.MAXIFS(รายชื่อจบส.!$L:$L,รายชื่อจบส.!$A:$A,$B4) -> 5
A5: 4-North | B5: FC382 | C5: หนองบัว 2 | D5: =COUNTIF(รายชื่อจบส.!$A:$A,$B5) -> 1 | E5: =COUNTIFS(รายชื่อจบส.!$A:$A,$B5,รายชื่อจบส.!$I:$I,"ผ่าน") -> 1 | F5: =E5-D5 -> 0 | G5: =IF(AND(D5>0,F5=0,H5<=7),3,IF(AND(D5>0,F5=0,H5<=11),2,IF(AND(D5>0,F5=0,H5=12),1,0))) -> 3 | H5: =_xlfn.MAXIFS(รายชื่อจบส.!$L:$L,รายชื่อจบส.!$A:$A,$B5) -> 7
A6: 4-North | B6: FC372 | C6: พญาเม็งราย (Type M) | D6: =COUNTIF(รายชื่อจบส.!$A:$A,$B6) -> 5 | E6: =COUNTIFS(รายชื่อจบส.!$A:$A,$B6,รายชื่อจบส.!$I:$I,"ผ่าน") -> 1 | F6: =E6-D6 -> -4 | G6: =IF(AND(D6>0,F6=0,H6<=7),3,IF(AND(D6>0,F6=0,H6<=11),2,IF(AND(D6>0,F6=0,H6=12),1,0))) -> 0 | H6: =_xlfn.MAXIFS(รายชื่อจบส.!$L:$L,รายชื่อจบส.!$A:$A,$B6) -> 3
A7: 4-North | B7: FC048 | C7: แม่สาย | D7: =COUNTIF(รายชื่อจบส.!$A:$A,$B7) -> 9 | E7: =COUNTIFS(รายชื่อจบส.!$A:$A,$B7,รายชื่อจบส.!$I:$I,"ผ่าน") -> 7 | F7: =E7-D7 -> -2 | G7: =IF(AND(D7>0,F7=0,H7<=7),3,IF(AND(D7>0,F7=0,H7<=11),2,IF(AND(D7>0,F7=0,H7=12),1,0))) -> 0 | H7: =_xlfn.MAXIFS(รายชื่อจบส.!$L:$L,รายชื่อจบส.!$A:$A,$B7) -> 9
A8: 4-North | B8: FC049 | C8: แม่จัน | D8: =COUNTIF(รายชื่อจบส.!$A:$A,$B8) -> 7 | E8: =COUNTIFS(รายชื่อจบส.!$A:$A,$B8,รายชื่อจบส.!$I:$I,"ผ่าน") -> 0 | F8: =E8-D8 -> -7 | G8: =IF(AND(D8>0,F8=0,H8<=7),3,IF(AND(D8>0,F8=0,H8<=11),2,IF(AND(D8>0,F8=0,H8=12),1,0))) -> 0 | H8: =_xlfn.MAXIFS(รายชื่อจบส.!$L:$L,รายชื่อจบส.!$A:$A,$B8) -> 0
A9: 4-North | B9: FC204 | C9: เชียงแสน | D9: =COUNTIF(รายชื่อจบส.!$A:$A,$B9) -> 6 | E9: =COUNTIFS(รายชื่อจบส.!$A:$A,$B9,รายชื่อจบส.!$I:$I,"ผ่าน") -> 0 | F9: =E9-D9 -> -6 | G9: =IF(AND(D9>0,F9=0,H9<=7),3,IF(AND(D9>0,F9=0,H9<=11),2,IF(AND(D9>0,F9=0,H9=12),1,0))) -> 0 | H9: =_xlfn.MAXIFS(รายชื่อจบส.!$L:$L,รายชื่อจบส.!$A:$A,$B9) -> 0
A10: 4-North | B10: 19FJ | C10: ลำปาง-ห้างฉัตร (Co-Area) | D10: =COUNTIF(รายชื่อจบส.!$A:$A,$B10) -> 2 | E10: =COUNTIFS(รายชื่อจบส.!$A:$A,$B10,รายชื่อจบส.!$I:$I,"ผ่าน") -> 1 | F10: =E10-D10 -> -1 | G10: =IF(AND(D10>0,F10=0,H10<=7),3,IF(AND(D10>0,F10=0,H10<=11),2,IF(AND(D10>0,F10=0,H10=12),1,0))) -> 0 | H10: =_xlfn.MAXIFS(รายชื่อจบส.!$L:$L,รายชื่อจบส.!$A:$A,$B10) -> 5
A11: 4-North | B11: FC194 | C11: พาน | D11: =COUNTIF(รายชื่อจบส.!$A:$A,$B11) -> 5 | E11: =COUNTIFS(รายชื่อจบส.!$A:$A,$B11,รายชื่อจบส.!$I:$I,"ผ่าน") -> 4 | F11: =E11-D11 -> -1 | G11: =IF(AND(D11>0,F11=0,H11<=7),3,IF(AND(D11>0,F11=0,H11<=11),2,IF(AND(D11>0,F11=0,H11=12),1,0))) -> 0 | H11: =_xlfn.MAXIFS(รายชื่อจบส.!$L:$L,รายชื่อจบส.!$A:$A,$B11) -> 4
A12: 4-North | B12: FC195 | C12: เวียงป่าเป้า | D12: =COUNTIF(รายชื่อจบส.!$A:$A,$B12) -> 2 | E12: =COUNTIFS(รายชื่อจบส.!$A:$A,$B12,รายชื่อจบส.!$I:$I,"ผ่าน") -> 2 | F12: =E12-D12 -> 0 | G12: =IF(AND(D12>0,F12=0,H12<=7),3,IF(AND(D12>0,F12=0,H12<=11),2,IF(AND(D12>0,F12=0,H12=12),1,0))) -> 3 | H12: =_xlfn.MAXIFS(รายชื่อจบส.!$L:$L,รายชื่อจบส.!$A:$A,$B12) -> 2
A13: 4-North | B13: FC247 | C13: แม่สรวย | D13: =COUNTIF(รายชื่อจบส.!$A:$A,$B13) -> 2 | E13: =COUNTIFS(รายชื่อจบส.!$A:$A,$B13,รายชื่อจบส.!$I:$I,"ผ่าน") -> 2 | F13: =E13-D13 -> 0 | G13: =IF(AND(D13>0,F13=0,H13<=7),3,IF(AND(D13>0,F13=0,H13<=11),2,IF(AND(D13>0,F13=0,H13=12),1,0))) -> 3 | H13: =_xlfn.MAXIFS(รายชื่อจบส.!$L:$L,รายชื่อจบส.!$A:$A,$B13) -> 5
... A82: 6-South | B82: FC040 | C82: เชี่ยวหลาน | D82: =COUNTIF(รายชื่อจบส.!$A:$A,$B82) -> 3 | E82: =COUNTIFS(รายชื่อจบส.!$A:$A,$B82,รายชื่อจบส.!$I:$I,"ผ่าน") -> 2 | F82: =E82-D82 -> -1 | G82: =IF(AND(D82>0,F82=0,H82<=7),3,IF(AND(D82>0,F82=0,H82<=11),2,IF(AND(D82>0,F82=0,H82=12),1,0))) -> 0 | H82: =_xlfn.MAXIFS(รายชื่อจบส.!$L:$L,รายชื่อจบส.!$A:$A,$B82) -> 4
A83: #N/A | B83: 3164 | C83: ปากน้ำชุมพร (N) | D83: =COUNTIF(รายชื่อจบส.!$A:$A,$B83) -> 13 | E83: =COUNTIFS(รายชื่อจบส.!$A:$A,$B83,รายชื่อจบส.!$I:$I,"ผ่าน") -> 1 | F83: =E83-D83 -> -12 | G83: =IF(AND(D83>0,F83=0,H83<=7),3,IF(AND(D83>0,F83=0,H83<=11),2,IF(AND(D83>0,F83=0,H83=12),1,0))) -> 0 | H83: =_xlfn.MAXIFS(รายชื่อจบส.!$L:$L,รายชื่อจบส.!$A:$A,$B83) -> 5
A84: 6-South | B84: FC287 | C84: มาบอำมฤต | D84: =COUNTIF(รายชื่อจบส.!$A:$A,$B84) -> 9 | E84: =COUNTIFS(รายชื่อจบส.!$A:$A,$B84,รายชื่อจบส.!$I:$I,"ผ่าน") -> 2 | F84: =E84-D84 -> -7 | G84: =IF(AND(D84>0,F84=0,H84<=7),3,IF(AND(D84>0,F84=0,H84<=11),2,IF(AND(D84>0,F84=0,H84=12),1,0))) -> 0 | H84: =_xlfn.MAXIFS(รายชื่อจบส.!$L:$L,รายชื่อจบส.!$A:$A,$B84) -> 8
A85: 6-South | B85: FC282 | C85: ระนอง | D85: =COUNTIF(รายชื่อจบส.!$A:$A,$B85) -> 6 | E85: =COUNTIFS(รายชื่อจบส.!$A:$A,$B85,รายชื่อจบส.!$I:$I,"ผ่าน") -> 2 | F85: =E85-D85 -> -4 | G85: =IF(AND(D85>0,F85=0,H85<=7),3,IF(AND(D85>0,F85=0,H85<=11),2,IF(AND(D85>0,F85=0,H85=12),1,0))) -> 0 | H85: =_xlfn.MAXIFS(รายชื่อจบส.!$L:$L,รายชื่อจบส.!$A:$A,$B85) -> 5
A86: 6-South | B86: FC129 | C86: ทุ่งใหญ่ | D86: =COUNTIF(รายชื่อจบส.!$A:$A,$B86) -> 5 | E86: =COUNTIFS(รายชื่อจบส.!$A:$A,$B86,รายชื่อจบส.!$I:$I,"ผ่าน") -> 5 | F86: =E86-D86 -> 0 | G86: =IF(AND(D86>0,F86=0,H86<=7),3,IF(AND(D86>0,F86=0,H86<=11),2,IF(AND(D86>0,F86=0,H86=12),1,0))) -> 3 | H86: =_xlfn.MAXIFS(รายชื่อจบส.!$L:$L,รายชื่อจบส.!$A:$A,$B86) -> 5
A87: 6-South | B87: FC253 | C87: นาสาร | D87: =COUNTIF(รายชื่อจบส.!$A:$A,$B87) -> 6 | E87: =COUNTIFS(รายชื่อจบส.!$A:$A,$B87,รายชื่อจบส.!$I:$I,"ผ่าน") -> 5 | F87: =E87-D87 -> -1 | G87: =IF(AND(D87>0,F87=0,H87<=7),3,IF(AND(D87>0,F87=0,H87<=11),2,IF(AND(D87>0,F87=0,H87=12),1,0))) -> 0 | H87: =_xlfn.MAXIFS(รายชื่อจบส.!$L:$L,รายชื่อจบส.!$A:$A,$B87) -> 5
A88: 6-South | B88: FC295 | C88: บางสวรรค์ 3 | D88: =COUNTIF(รายชื่อจบส.!$A:$A,$B88) -> 4 | E88: =COUNTIFS(รายชื่อจบส.!$A:$A,$B88,รายชื่อจบส.!$I:$I,"ผ่าน") -> 0 | F88: =E88-D88 -> -4 | G88: =IF(AND(D88>0,F88=0,H88<=7),3,IF(AND(D88>0,F88=0,H88<=11),2,IF(AND(D88>0,F88=0,H88=12),1,0))) -> 0 | H88: =_xlfn.MAXIFS(รายชื่อจบส.!$L:$L,รายชื่อจบส.!$A:$A,$B88) -> 0
A89: 6-South | B89: FC356 | C89: นาสาร 2 | D89: =COUNTIF(รายชื่อจบส.!$A:$A,$B89) -> 0 | E89: =COUNTIFS(รายชื่อจบส.!$A:$A,$B89,รายชื่อจบส.!$I:$I,"ผ่าน") -> 0 | F89: =E89-D89 -> 0 | G89: =IF(AND(D89>0,F89=0,H89<=7),3,IF(AND(D89>0,F89=0,H89<=11),2,IF(AND(D89>0,F89=0,H89=12),1,0))) -> 0 | H89: =_xlfn.MAXIFS(รายชื่อจบส.!$L:$L,รายชื่อจบส.!$A:$A,$B89) -> 0
A90: 6-South | B90: FC396 | C90: เวียงสระ | D90: =COUNTIF(รายชื่อจบส.!$A:$A,$B90) -> 5 | E90: =COUNTIFS(รายชื่อจบส.!$A:$A,$B90,รายชื่อจบส.!$I:$I,"ผ่าน") -> 4 | F90: =E90-D90 -> -1 | G90: =IF(AND(D90>0,F90=0,H90<=7),3,IF(AND(D90>0,F90=0,H90<=11),2,IF(AND(D90>0,F90=0,H90=12),1,0))) -> 0 | H90: =_xlfn.MAXIFS(รายชื่อจบส.!$L:$L,รายชื่อจบส.!$A:$A,$B90) -> 5
A91: 6-South | B91: FC127 | C91: ปัตตานี | D91: =COUNTIF(รายชื่อจบส.!$A:$A,$B91) -> 10 | E91: =COUNTIFS(รายชื่อจบส.!$A:$A,$B91,รายชื่อจบส.!$I:$I,"ผ่าน") -> 8 | F91: =E91-D91 -> -2 | G91: =IF(AND(D91>0,F91=0,H91<=7),3,IF(AND(D91>0,F91=0,H91<=11),2,IF(AND(D91>0,F91=0,H91=12),1,0))) -> 0 | H91: =_xlfn.MAXIFS(รายชื่อจบส.!$L:$L,รายชื่อจบส.!$A:$A,$B91) -> 4
A92: 6-South | B92: FC166 | C92: บ่อทอง | D92: =COUNTIF(รายชื่อจบส.!$A:$A,$B92) -> 6 | E92: =COUNTIFS(รายชื่อจบส.!$A:$A,$B92,รายชื่อจบส.!$I:$I,"ผ่าน") -> 5 | F92: =E92-D92 -> -1 | G92: =IF(AND(D92>0,F92=0,H92<=7),3,IF(AND(D92>0,F92=0,H92<=11),2,IF(AND(D92>0,F92=0,H92=12),1,0))) -> 0 | H92: =_xlfn.MAXIFS(รายชื่อจบส.!$L:$L,รายชื่อจบส.!$A:$A,$B92) -> 4
A93: 6-South | B93: 3165 | C93: ผาหลวงคอนกรีต (N) | D93: =COUNTIF(รายชื่อจบส.!$A:$A,$B93) -> 4 | E93: =COUNTIFS(รายชื่อจบส.!$A:$A,$B93,รายชื่อจบส.!$I:$I,"ผ่าน") -> 1 | F93: =E93-D93 -> -3 | G93: =IF(AND(D93>0,F93=0,H93<=7),3,IF(AND(D93>0,F93=0,H93<=11),2,IF(AND(D93>0,F93=0,H93=12),1,0))) -> 0 | H93: =_xlfn.MAXIFS(รายชื่อจบส.!$L:$L,รายชื่อจบส.!$A:$A,$B93) -> 10
A94: 6-South | B94: 3166 | C94: ผาหลวง 2(N) | D94: =COUNTIF(รายชื่อจบส.!$A:$A,$B94) -> 2 | E94: =COUNTIFS(รายชื่อจบส.!$A:$A,$B94,รายชื่อจบส.!$I:$I,"ผ่าน") -> 2 | F94: =E94-D94 -> 0 | G94: =IF(AND(D94>0,F94=0,H94<=7),3,IF(AND(D94>0,F94=0,H94<=11),2,IF(AND(D94>0,F94=0,H94=12),1,0))) -> 2 | H94: =_xlfn.MAXIFS(รายชื่อจบส.!$L:$L,รายชื่อจบส.!$A:$A,$B94) -> 10
A95: 6-South | B95: FC072 | C95: สิงหนคร | D95: =COUNTIF(รายชื่อจบส.!$A:$A,$B95) -> 7 | E95: =COUNTIFS(รายชื่อจบส.!$A:$A,$B95,รายชื่อจบส.!$I:$I,"ผ่าน") -> 4 | F95: =E95-D95 -> -3 | G95: =IF(AND(D95>0,F95=0,H95<=7),3,IF(AND(D95>0,F95=0,H95<=11),2,IF(AND(D95>0,F95=0,H95=12),1,0))) -> 0 | H95: =_xlfn.MAXIFS(รายชื่อจบส.!$L:$L,รายชื่อจบส.!$A:$A,$B95) -> 3
... A288: 5-NorthEast | B288: FC405 | C288: FC พังโคน 2 | D288: =COUNTIF(รายชื่อจบส.!$A:$A,$B288) -> 2 | E288: =COUNTIFS(รายชื่อจบส.!$A:$A,$B288,รายชื่อจบส.!$I:$I,"ผ่าน") -> 2 | F288: =E288-D288 -> 0 | G288: =IF(AND(D288>0,F288=0,H288<=7),3,IF(AND(D288>0,F288=0,H288<=11),2,IF(AND(D288>0,F288=0,H288=12),1,0))) -> 2 | H288: =_xlfn.MAXIFS(รายชื่อจบส.!$L:$L,รายชื่อจบส.!$A:$A,$B288) -> 8

Sheet จบส.ไม่มี
A1: รหัสโรงงาน | B1: REGION | C1: บจก./หจก. | D1: ลำดับ | E1: รหัส | F1: ชื่อภาษาไทย | G1: นามสกุลภาษาไทย | H1: โรงงาน | I1: Status | J1: TEAM | K1: ชื่อ-นามสกุล | L1: เดือนที่อบรม
A2: FC360 | B2: 4-North | C2: หจก.เกษมชัยพานิช | D2: 1 | E2: VE0007 | F2: นายชัยอรุณ | G2: ต้องใจ | H2: วังเหนือ | I2: ยังไม่อบรม | J2: ชัยณรงค์ | K2: นายชัยอรุณต้องใจ | L2: ยังไม่อบรม
A3: FC348 | B3: 4-North | C3: หจก.ที เอ็น ดับเบิ้ลยู เชียงดาวก่อสร้าง | D3: 1 | E3: UX0023 | F3: ไสว | G3: จะงาม | H3: เชียงดาว | I3: ยังไม่อบรม | J3: เสฎฐวุฒิ | K3: ไสวจะงาม | L3: ยังไม่อบรม
