Workbook
Name Datalist: OFFSET('[2]Data-CPAC'!$A$1,0,0,COUNTA('[2]Data-CPAC'!$A:$A),COUNTA('[2]Data-CPAC'!$1:$1))
Name DAYS: [1]ข้อมูล!$J$12:$L$198
Name Summary: [1]ข้อมูล!$BD$3

Sheet L1L2
I1: ทดสอบปฏิบัติ พนง.โยธา
H2: ทดสอบทฤษฎีระดับพื้นฐานพนักงานผลิต(L1) | I2: ทดสอบปฏิบัติระดับพื้นฐานพนักงานผลิต(L1) | J2: ทดสอบทฤษฎีระดับสามัญพนักงานผลิต(L2) | K2: ทดสอบปฏิบัติระดับสามัญพนักงานผลิต(L2)
B3: เอาข้อมูลจาก BLUENET มาวาง ต้อง Pivot มาวางเพราะชื่อซ้ำ | H3: หลักสูตรอบรม | R3: UPDATE
A4: กิจการ | B4: รหัสพนักงาน | C4: ชื่อ - นามสกุล | D4: Franchisee | E4: โรงงาน | F4: ตำแหน่ง | G4: อายุงาน (ปี) | H4: ทฤษฎีระดับพื้นฐาน(L1) | I4: ปฏิบัติระดับพื้นฐาน(L1) | J4: ทฤษฎีระดับสามัญ(L2) | K4: ปฏิบัติระดับสามัญ(L2) | L4: จำนวนหลักสูตรที่ผ่าน | M4: รหัสโรงงาน | N4: ชื่อโรงงาน | O4: หจก./บจก. | P4: ทีมงาน | Q4: เปิด/ปิด | R4: 7 sep.
A5: 2-East | B5: FR002005 | C5: ประชา มนตรี | D5: FR002 : บจก.สหชัยธุรกิจก่อสร้าง 1993 | E5: FC046 : วังม่วง | F5: พนักงานบริการโรงงาน | G5: 24 | H5: ผ่าน | I5: ผ่าน | J5: ผ่าน | K5: ผ่าน | L5: ผ่าน | M5: FC046 | N5: วังม่วง | O5: บจก.สหชัยธุรกิจก่อสร้าง 1993 | P5: อดิเรก | Q5: A
A6: 2-East | B6: FR002008 | C6: กัมปนาท พุ่มบ้านเซ่า | D6: FR002 : บจก.สหชัยธุรกิจก่อสร้าง 1993 | E6: FC139 : คลอง 11 | F6: พนักงานผลิต | G6: 15 | H6: ผ่าน | I6: ผ่าน | J6: ผ่าน | K6: ผ่าน | L6: ผ่าน | M6: FC139 | N6: คลอง 11 | O6: บจก.สหชัยธุรกิจก่อสร้าง 1993 | P6: ประสิทธิ์ | Q6: A
A7: 2-East | B7: FR002011 | C7: สันติ นุงกระโทก | D7: FR002 : บจก.สหชัยธุรกิจก่อสร้าง 1993 | E7: FC095 : มวกเหล็ก | F7: พนักงานผลิต | G7: 14 | H7: ผ่าน | I7: ผ่าน | J7: ผ่าน | K7: ผ่าน | L7: ผ่าน | M7: FC095 | N7: มวกเหล็ก | O7: บจก.สหชัยธุรกิจก่อสร้าง 1993 | P7: อดิเรก | Q7: A
A8: 2-East | B8: FR002018 | C8: ฉัตรชัย ฟองลม | D8: FR002 : บจก.สหชัยธุรกิจก่อสร้าง 1993 | E8: FC046 : วังม่วง | F8: พ.บริการงานผลิต(QC) | G8: 10 | H8: ผ่าน | I8: ผ่าน | J8: ผ่าน | K8: ผ่าน | L8: ผ่าน | M8: FC046 | N8: วังม่วง | O8: บจก.สหชัยธุรกิจก่อสร้าง 1993 | P8: อดิเรก | Q8: A
A9: 2-East | B9: FR002024 | C9: ปรางทอง งามเนตร | D9: FR002 : บจก.สหชัยธุรกิจก่อสร้าง 1993 | E9: FC046 : วังม่วง | F9: พนักงานผลิต | G9: 10 | H9: ผ่าน | I9: ผ่าน | J9: ผ่าน | K9: ผ่าน | L9: ผ่าน | M9: FC046 | N9: วังม่วง | O9: บจก.สหชัยธุรกิจก่อสร้าง 1993 | P9: อดิเรก | Q9: A
A10: 2-East | B10: FR002025 | C10: ชาญวิทย์ วงษา | D10: FR002 : บจก.สหชัยธุรกิจก่อสร้าง 1993 | E10: FC095 : มวกเหล็ก | F10: พนักงานบริการโรงงาน | G10: 24 | H10: ไม่ผ่าน | I10: ไม่ผ่าน | J10: ไม่ผ่าน | K10: ไม่ผ่าน | L10: ไม่ผ่าน | M10: FC095 | N10: มวกเหล็ก | O10: บจก.สหชัยธุรกิจก่อสร้าง 1993 | P10: อดิเรก | Q10: A
A11: 2-East | B11: FR002027 | C11: ขจรศักดิ์ ผิวขำ | D11: FR002 : บจก.สหชัยธุรกิจก่อสร้าง 1993 | E11: FC175 : พัฒนานิคม | F11: พนักงานผลิต | G11: 10 | H11: ผ่าน | I11: ผ่าน | J11: ผ่าน | K11: ผ่าน | L11: ผ่าน | M11: FC175 | N11: พัฒนานิคม | O11: บจก.สหชัยธุรกิจก่อสร้าง 1993 | P11: อดิเรก | Q11: A
A12: 2-East | B12: FR002029 | C12: สุพกิจ เกตุยา | D12: FR002 : บจก.สหชัยธุรกิจก่อสร้าง 1993 | E12: FC175 : พัฒนานิคม | F12: พนักงานบริการโรงงาน | G12: 18 | H12: ไม่ผ่าน | I12: ไม่ผ่าน | J12: ไม่ผ่าน | K12: ไม่ผ่าน | L12: ไม่ผ่าน | M12: FC175 | N12: พัฒนานิคม | O12: บจก.สหชัยธุรกิจก่อสร้าง 1993 | P12: อดิเรก | Q12: A
A13: 2-East | B13: FR002030 | C13: กฤษฎา หมื่นอาจ | D13: FR002 : บจก.สหชัยธุรกิจก่อสร้าง 1993 | E13: FC046 : วังม่วง | F13: พนักงานผลิต | G13: 4 | H13: ผ่าน | I13: ผ่าน | J13: ผ่าน | K13: ผ่าน | L13: ผ่าน | M13: FC046 | N13: วังม่วง | O13: บจก.สหชัยธุรกิจก่อสร้าง 1993 | P13: อดิเรก | Q13: A
A14: 2-East | B14: FR002031 | C14: ยุทธนา พิมพา | D14: FR002 : บจก.สหชัยธุรกิจก่อสร้าง 1993 | E14: FC175 : พัฒนานิคม | F14: พ.บริการงานผลิต(QC) | G14: 4 | H14: ผ่าน | I14: ผ่าน | J14: ผ่าน | K14: ผ่าน | L14: ผ่าน | M14: FC175 | N14: พัฒนานิคม | O14: บจก.สหชัยธุรกิจก่อสร้าง 1993 | P14: อดิเรก | Q14: A
A15: 2-East | B15: FR002032 | C15: ชัยวัฒน์ สามารถ | D15: FR002 : บจก.สหชัยธุรกิจก่อสร้าง 1993 | E15: FC046 : วังม่วง | F15: พ.บริการงานผลิต(QC) | G15: 4 | H15: ผ่าน | I15: ผ่าน | J15: ผ่าน | K15: ผ่าน | L15: ผ่าน | M15: FC139 | N15: คลอง 11 | O15: บจก.สหชัยธุรกิจก่อสร้าง 1993 | P15: อดิเรก | Q15: A
A16: 2-East | B16: FR002033 | C16: บุญเกิด คำแสน | D16: FR002 : บจก.สหชัยธุรกิจก่อสร้าง 1993 | E16: FC095 : มวกเหล็ก | F16: พนักงานผลิต | G16: 4 | H16: ผ่าน | I16: ผ่าน | J16: ผ่าน | K16: ผ่าน | L16: ผ่าน | M16: FC095 | N16: มวกเหล็ก | O16: บจก.สหชัยธุรกิจก่อสร้าง 1993 | P16: อดิเรก | Q16: A
... A24: 2-East | B24: FR002042 | C24: นันทิวร วันนา | D24: FR002 : บจก.สหชัยธุรกิจก่อสร้าง 1993 | E24: FC175 : พัฒนานิคม | F24: พ.บริการผลิต(โยธา) | G24: 1 | H24: ไม่ต้องสอบ | I24: ผ่าน | J24: ไม่ต้องสอบ | K24: ไม่ต้องสอบ | L24: ผ่าน | M24: FC175 | N24: พัฒนานิคม | O24: บจก.สหชัยธุรกิจก่อสร้าง 1993 | P24: อดิเรก | Q24: A
A25: 0 | B25: FR003001 | C25: อุดมชัย รุชะดา | D25: FR003 : บจก.ศุภภัณฑ์คอนกรีต | E25: FC215 : ดาวเรือง 2 | F25: พนักงานผลิต | G25: 15 | H25: ผ่าน | I25: ผ่าน | J25: ผ่าน | K25: ผ่าน | L25: ผ่าน | M25: FC215 | N25: FC215 : ดาวเรือง 2 | O25: 0 | P25: 0 | Q25: C
A26: 0 | B26: FR003002 | C26: สุรศักดิ์ ฉิมทอง | D26: FR003 : บจก.ศุภภัณฑ์คอนกรีต | E26: FC215 : ดาวเรือง 2 | F26: พนักงานผลิต | G26: 12 | H26: ผ่าน | I26: ผ่าน | J26: ผ่าน | K26: ผ่าน | L26: ผ่าน | M26: FC215 | N26: FC215 : ดาวเรือง 2 | O26: 0 | P26: 0 | Q26: C
A27: 0 | B27: FR003003 | C27: ธีระวุฒิ พูลทวี | D27: FR003 : บจก.ศุภภัณฑ์คอนกรีต | E27: FC215 : ดาวเรือง 2 | F27: พ.บริการงานผลิต(QC) | G27: 12 | H27: ผ่าน | I27: ผ่าน | J27: ผ่าน | K27: ผ่าน | L27: ผ่าน | M27: FC215 | N27: FC215 : ดาวเรือง 2 | O27: 0 | P27: 0 | Q27: C
A28: 2-East | B28: FR003005 | C28: สรัญญู สีหาโหวด | D28: FR003 : บจก.ศุภภัณฑ์คอนกรีต | E28: FC111 : ดาวเรือง | F28: พนักงานผลิต | G28: 19 | H28: ผ่าน | I28: ผ่าน | J28: ผ่าน | K28: ผ่าน | L28: ผ่าน | M28: FC111 | N28: ดาวเรือง 1 | O28: บจก.ศุภภัณฑ์คอนกรีต | P28: อดิเรก | Q28: A
A29: 2-East | B29: FR003006 | C29: อภิชาติ เดชเสน | D29: FR003 : บจก.ศุภภัณฑ์คอนกรีต | E29: FC111 : ดาวเรือง | F29: พนักงานผลิต | G29: 12 | H29: ผ่าน | I29: ผ่าน | J29: ผ่าน | K29: ผ่าน | L29: ผ่าน | M29: FC111 | N29: ดาวเรือง 1 | O29: บจก.ศุภภัณฑ์คอนกรีต | P29: อดิเรก | Q29: A
A30: 2-East | B30: FR003007 | C30: ปณิธาน พันธ์แก้ว | D30: FR003 : บจก.ศุภภัณฑ์คอนกรีต | E30: FC111 : ดาวเรือง | F30: พ.บริการงานผลิต(QC) | G30: 12 | H30: ผ่าน | I30: ผ่าน | J30: ผ่าน | K30: ผ่าน | L30: ผ่าน | M30: FC111 | N30: ดาวเรือง 1 | O30: บจก.ศุภภัณฑ์คอนกรีต | P30: อดิเรก | Q30: A
A31: 3-West | B31: FR004002 | C31: รุจิภาส บุญยิ้ม | D31: FR004 : หจก.งามยิ่งเจริญคอนกรีต | E31: FC197 : สรรคบุรี | F31: พ.บริการผลิต(โยธา) | G31: 16 | H31: ไม่ต้องสอบ | I31: ผ่าน | J31: ไม่ต้องสอบ | K31: ไม่ต้องสอบ | L31: ผ่าน | M31: FC197 | N31: สรรคบุรี | O31: หจก.งามยิ่งเจริญคอนกรีต | P31: สามารถ | Q31: A
A32: 2-East | B32: FR004003 | C32: โชคชัย งามวิจิตรอร่าม | D32: FR004 : หจก.งามยิ่งเจริญคอนกรีต | E32: FC015 : บ้านหมี่ | F32: ผู้จัดการโรงงาน | G32: 25 | H32: ไม่ต้องสอบ | I32: ไม่ต้องสอบ | J32: ไม่ต้องสอบ | K32: ไม่ต้องสอบ | L32: ผ่าน | M32: FC015 | N32: บ้านหมี่ | O32: หจก.งามยิ่งเจริญคอนกรีต | P32: อดิเรก | Q32: A
A33: 2-East | B33: FR004004 | C33: วงศ์วรรณรักษ์ ดวงอินทร์ | D33: FR004 : หจก.งามยิ่งเจริญคอนกรีต | E33: FC015 : บ้านหมี่ | F33: พนักงานผลิต | G33: 24 | H33: ผ่าน | I33: ผ่าน | J33: ผ่าน | K33: ผ่าน | L33: ผ่าน | M33: FC015 | N33: บ้านหมี่ | O33: หจก.งามยิ่งเจริญคอนกรีต | P33: อดิเรก | Q33: A
A34: 2-East | B34: FR004005 | C34: พงศกร นาคกุล | D34: FR004 : หจก.งามยิ่งเจริญคอนกรีต | E34: FC015 : บ้านหมี่ | F34: พ.บริการผลิต(โยธา) | G34: 10 | H34: ไม่ต้องสอบ | I34: ผ่าน | J34: ไม่ต้องสอบ | K34: ไม่ต้องสอบ | L34: ผ่าน | M34: FC015 | N34: บ้านหมี่ | O34: หจก.งามยิ่งเจริญคอนกรีต | P34: อดิเรก | Q34: A
A35: 3-West | B35: FR004006 | C35: ชลธิดา ปึ่งประกายศรี | D35: FR004 : หจก.งามยิ่งเจริญคอนกรีต | E35: FC197 : สรรคบุรี | F35: พนักงานผลิต | G35: 9 | H35: ผ่าน | I35: ผ่าน | J35: ผ่าน | K35: ผ่าน | L35: ผ่าน | M35: FC197 | N35: สรรคบุรี | O35: หจก.งามยิ่งเจริญคอนกรีต | P35: สามารถ | Q35: A
A36: 3-West | B36: FR004007 | C36: นายอภินันท์ ชูชัย | D36: FR004 : หจก.งามยิ่งเจริญคอนกรีต | E36: FC197 : สรรคบุรี | F36: พ.บริการผลิต(โยธา) | G36: 0 | H36: ไม่ต้องสอบ | I36: ผ่าน | J36: ไม่ต้องสอบ | K36: ไม่ต้องสอบ | L36: ผ่าน | M36: FC197 | N36: สรรคบุรี | O36: หจก.งามยิ่งเจริญคอนกรีต | P36: สามารถ | Q36: A
A37: 2-East | B37: FR005002 | C37: ชัชวาลย์ น้อยใหญ่ | D37: FR005 : บจก.นิธิศพันธ์ | E37: FC013 : ลำนารายณ์ | F37: พนักงานผลิต | G37: 17 | H37: ผ่าน | I37: ผ่าน | J37: ผ่าน | K37: ผ่าน | L37: ผ่าน | M37: FC013 | N37: ลำนารายณ์ | O37: บจก.นิธิศพันธ์ | P37: อดิเรก | Q37: A
A38: 2-East | B38: FR005003 | C38: ทรงยศ เกษทอง | D38: FR005 : บจก.นิธิศพันธ์ | E38: FC013 : ลำนารายณ์ | F38: พ.บริการงานผลิต(QC) | G38: 12 | H38: ผ่าน | I38: ผ่าน | J38: ผ่าน | K38: ผ่าน | L38: ผ่าน | M38: FC013 | N38: ลำนารายณ์ | O38: บจก.นิธิศพันธ์ | P38: อดิเรก | Q38: A
A39: 2-East | B39: FR005006 | C39: ราชัญ หรบรรณ์ | D39: FR005 : บจก.นิธิศพันธ์ | E39: FC013 : ลำนารายณ์ | F39: พ.บริการผลิต(โยธา) | G39: 0 | H39: ไม่ต้องสอบ | I39: ผ่าน | J39: ไม่ต้องสอบ | K39: ไม่ต้องสอบ | L39: ผ่าน | M39: FC013 | N39: ลำนารายณ์ | O39: บจก.นิธิศพันธ์ | P39: อดิเรก | Q39: A
... A139: 3-West | B139: FR017015 | C139: อัทธวัจน์ ต๊ะอินทร์ | D139: FR017 : บจก.ต.แสงพัฒนาคอนกรีต | E139: FC142 : บางปลาม้า | F139: พ.บริการงานผลิต(QC) | G139: 9 | H139: ผ่าน | I139: ผ่าน | J139: ผ่าน | K139: ผ่าน | L139: ผ่าน | M139: FC142 | N139: บางปลาม้า | O139: บจก.ต.แสงพัฒนาคอนกรีต | P139: สามารถ | Q139: A
A140: 0 | B140: FR018001 | C140: นพพล ลวรรณวงษ์ | D140: FR018 : บจก.ซี.พี.เอส.คอนกรีต | E140: FC093 : สามชุก | F140: พนักงานผลิต | G140: 19 | H140: ผ่าน | I140: ผ่าน | J140: ผ่าน | K140: ผ่าน | L140: ผ่าน | M140: FC093 | N140: FC093 : สามชุก | O140: 0 | P140: 0 | Q140: C
A141: 0 | B141: FR018004 | C141: วีรศักดิ์ รอดห้อย | D141: FR018 : บจก.ซี.พี.เอส.คอนกรีต | E141: FC093 : สามชุก | F141: พ.บริการงานผลิต(QC) | G141: 10 | H141: ผ่าน | I141: ผ่าน | J141: ผ่าน | K141: ผ่าน | L141: ผ่าน | M141: FC093 | N141: FC093 : สามชุก | O141: 0 | P141: 0 | Q141: C
A142: 0 | B142: FR018006 | C142: วินัย คล้ายขำ | D142: FR018 : บจก.ซี.พี.เอส.คอนกรีต | E142: FC093 : สามชุก | F142: พ.บริการผลิต(โยธา) | G142: 9 | H142: ไม่ต้องสอบ | I142: ผ่าน | J142: ไม่ต้องสอบ | K142: ไม่ต้องสอบ | L142: ผ่าน | M142: FC093 | N142: FC093 : สามชุก | O142: 0 | P142: 0 | Q142: C
A143: 0 | B143: FR018007 | C143: ธวัชชัย ช่อผกา | D143: FR018 : บจก.ซี.พี.เอส.คอนกรีต | E143: FC093 : สามชุก | F143: พ.บริการงานผลิต(QC) | G143: 9 | H143: ผ่าน | I143: ผ่าน | J143: ผ่าน | K143: ผ่าน | L143: ผ่าน | M143: FC093 | N143: FC093 : สามชุก | O143: 0 | P143: 0 | Q143: C
A144: 3-West | B144: FR019001 | C144: ยอดชาย น้ำพระทัย | D144: FR019 : บจก.กอวัฒนาคอนกรีต | E144: FC070 : ท่ามะกา | F144: พนักงานบริการโรงงาน | G144: 27 | H144: ผ่าน | I144: ผ่าน | J144: ผ่าน | K144: ผ่าน | L144: ผ่าน | M144: FC070 | N144: ท่ามะกา | O144: บจก.กอวัฒนาคอนกรีต | P144: เอกพล | Q144: A
A145: 3-West | B145: FR019002 | C145: ภาณุพงศ์ สวยล้ำ | D145: FR019 : บจก.กอวัฒนาคอนกรีต | E145: FC070 : ท่ามะกา | F145: พ.บริการผลิต(Operator) | G145: 13 | H145: ผ่าน | I145: ผ่าน | J145: ผ่าน | K145: ผ่าน | L145: ผ่าน | M145: FC070 | N145: ท่ามะกา | O145: บจก.กอวัฒนาคอนกรีต | P145: เอกพล | Q145: A
A146: 3-West | B146: FR019005 | C146: ศรราม จินดากุลย์ | D146: FR019 : บจก.กอวัฒนาคอนกรีต | E146: FC254 : พนมทวน | F146: พนักงานบริการโรงงาน | G146: 11 | H146: ผ่าน | I146: ผ่าน | J146: ผ่าน | K146: ผ่าน | L146: ผ่าน | M146: FC254 | N146: พนมทวน | O146: บจก.กอวัฒนาคอนกรีต | P146: เอกพล | Q146: A
...

Sheet Score
A1: กิจการ | B1: FCPLNO | C1: โรงงาน | D1: จำนวน พนง. | E1: ผ่าน | F1: Score จำนวน พนง. | G1: Score (L1L2) | H1: M | I1: บจก./หจก. | J1: เปลี่ยนคน
A2: 5-NorthEast | B2: ZZP1 | C2: อุบลรัตน์ (X2) | D2: =COUNTIF(L1L2!$M:$M,$B2) -> 0 | E2: =COUNTIFS(L1L2!$M:$M,$B2,L1L2!$L:$L,$E$1) -> 0 | F2: =IF(AND(H2=1,D2>=2),9,IF(D2>=3,9,0)) -> 0 | G2: =IF(AND(H2=1,E2>=2),3,IF(E2>3,3,E2)) -> 0 | H2: =IF(ISNUMBER(SEARCH("M", C2)), 1, 0) -> 0 | I2: =VLOOKUP(B2,Sheet1!$A:$E,5,FALSE) -> บจก.เคแพคคอนกรีต 2004
A3: 5-NorthEast | B3: ZZP2 | C3: น้ำพอง(X2) | D3: =COUNTIF(L1L2!$M:$M,$B3) -> 3 | E3: =COUNTIFS(L1L2!$M:$M,$B3,L1L2!$L:$L,$E$1) -> 1 | F3: =IF(AND(H3=1,D3>=2),9,IF(D3>=3,9,0)) -> 9 | G3: =IF(AND(H3=1,E3>=2),3,IF(E3>3,3,E3)) -> 1 | H3: =IF(ISNUMBER(SEARCH("M", C3)), 1, 0) -> 0 | I3: =VLOOKUP(B3,Sheet1!$A:$E,5,FALSE) -> บจก.เคแพคคอนกรีต 2004
A4: 5-NorthEast | B4: ZZP3 | C4: ขอนแก่น 1(X2) | D4: =COUNTIF(L1L2!$M:$M,$B4) -> 4 | E4: =COUNTIFS(L1L2!$M:$M,$B4,L1L2!$L:$L,$E$1) -> 4 | F4: =IF(AND(H4=1,D4>=2),9,IF(D4>=3,9,0)) -> 9 | G4: =IF(AND(H4=1,E4>=2),3,IF(E4>3,3,E4)) -> 3 | H4: =IF(ISNUMBER(SEARCH("M", C4)), 1, 0) -> 0 | I4: =VLOOKUP(B4,Sheet1!$A:$E,5,FALSE) -> บจก.เคแพคคอนกรีต 2004
A5: 5-NorthEast | B5: ZZP4 | C5: ขอนแก่น 2(X2) | D5: =COUNTIF(L1L2!$M:$M,$B5) -> 3 | E5: =COUNTIFS(L1L2!$M:$M,$B5,L1L2!$L:$L,$E$1) -> 3 | F5: =IF(AND(H5=1,D5>=2),9,IF(D5>=3,9,0)) -> 9 | G5: =IF(AND(H5=1,E5>=2),3,IF(E5>3,3,E5)) -> 3 | H5: =IF(ISNUMBER(SEARCH("M", C5)), 1, 0) -> 0 | I5: =VLOOKUP(B5,Sheet1!$A:$E,5,FALSE) -> บจก.เคแพคคอนกรีต 2004
A6: 5-NorthEast | B6: ZZP5 | C6: ท่าพระ(X2) | D6: =COUNTIF(L1L2!$M:$M,$B6) -> 3 | E6: =COUNTIFS(L1L2!$M:$M,$B6,L1L2!$L:$L,$E$1) -> 2 | F6: =IF(AND(H6=1,D6>=2),9,IF(D6>=3,9,0)) -> 9 | G6: =IF(AND(H6=1,E6>=2),3,IF(E6>3,3,E6)) -> 2 | H6: =IF(ISNUMBER(SEARCH("M", C6)), 1, 0) -> 0 | I6: =VLOOKUP(B6,Sheet1!$A:$E,5,FALSE) -> บจก.เคแพคคอนกรีต 2004
A7: 5-NorthEast | B7: ZZP8 | C7: หนองเรือ(X2) | D7: =COUNTIF(L1L2!$M:$M,$B7) -> 4 | E7: =COUNTIFS(L1L2!$M:$M,$B7,L1L2!$L:$L,$E$1) -> 3 | F7: =IF(AND(H7=1,D7>=2),9,IF(D7>=3,9,0)) -> 9 | G7: =IF(AND(H7=1,E7>=2),3,IF(E7>3,3,E7)) -> 3 | H7: =IF(ISNUMBER(SEARCH("M", C7)), 1, 0) -> 0 | I7: =VLOOKUP(B7,Sheet1!$A:$E,5,FALSE) -> บจก.เคแพคคอนกรีต 2004
A8: 5-NorthEast | B8: ZZTA | C8: โนนสะอาดType X2 | D8: =COUNTIF(L1L2!$M:$M,$B8) -> 3 | E8: =COUNTIFS(L1L2!$M:$M,$B8,L1L2!$L:$L,$E$1) -> 3 | F8: =IF(AND(H8=1,D8>=2),9,IF(D8>=3,9,0)) -> 9 | G8: =IF(AND(H8=1,E8>=2),3,IF(E8>3,3,E8)) -> 3 | H8: =IF(ISNUMBER(SEARCH("M", C8)), 1, 0) -> 0 | I8: =VLOOKUP(B8,Sheet1!$A:$E,5,FALSE) -> บจก.เคแพคคอนกรีต 2004
A9: 5-NorthEast | B9: FC081 | C9: ปราสาท | D9: =COUNTIF(L1L2!$M:$M,$B9) -> 4 | E9: =COUNTIFS(L1L2!$M:$M,$B9,L1L2!$L:$L,$E$1) -> 4 | F9: =IF(AND(H9=1,D9>=2),9,IF(D9>=3,9,0)) -> 9 | G9: =IF(AND(H9=1,E9>=2),3,IF(E9>3,3,E9)) -> 3 | H9: =IF(ISNUMBER(SEARCH("M", C9)), 1, 0) -> 0 | I9: =VLOOKUP(B9,Sheet1!$A:$E,5,FALSE) -> บจก.เจ.เค.คอนกรีต
A10: 1-Metro | B10: 31ED | C10: หลวงแพ่ง (N) | D10: =COUNTIF(L1L2!$M:$M,$B10) -> 3 | E10: =COUNTIFS(L1L2!$M:$M,$B10,L1L2!$L:$L,$E$1) -> 3 | F10: =IF(AND(H10=1,D10>=2),9,IF(D10>=3,9,0)) -> 9 | G10: =IF(AND(H10=1,E10>=2),3,IF(E10>3,3,E10)) -> 3 | H10: =IF(ISNUMBER(SEARCH("M", C10)), 1, 0) -> 0 | I10: =VLOOKUP(B10,Sheet1!$A:$E,5,FALSE) -> บจก.เจเอ็นเจพี ซิเมนต์
A11: 4-North | B11: FC045 | C11: ขาณุวรลักษบุรี | D11: =COUNTIF(L1L2!$M:$M,$B11) -> 3 | E11: =COUNTIFS(L1L2!$M:$M,$B11,L1L2!$L:$L,$E$1) -> 3 | F11: =IF(AND(H11=1,D11>=2),9,IF(D11>=3,9,0)) -> 9 | G11: =IF(AND(H11=1,E11>=2),3,IF(E11>3,3,E11)) -> 3 | H11: =IF(ISNUMBER(SEARCH("M", C11)), 1, 0) -> 0 | I11: =VLOOKUP(B11,Sheet1!$A:$E,5,FALSE) -> บจก.เจริญภัณฑ์ผลิตคอนกรีต
A12: 4-North | B12: FC067 | C12: ท่าตะโก | D12: =COUNTIF(L1L2!$M:$M,$B12) -> 5 | E12: =COUNTIFS(L1L2!$M:$M,$B12,L1L2!$L:$L,$E$1) -> 5 | F12: =IF(AND(H12=1,D12>=2),9,IF(D12>=3,9,0)) -> 9 | G12: =IF(AND(H12=1,E12>=2),3,IF(E12>3,3,E12)) -> 3 | H12: =IF(ISNUMBER(SEARCH("M", C12)), 1, 0) -> 0 | I12: =VLOOKUP(B12,Sheet1!$A:$E,5,FALSE) -> บจก.เจริญภัณฑ์ผลิตคอนกรีต
A13: 4-North | B13: FC289 | C13: คลองขลุง 2 | D13: =COUNTIF(L1L2!$M:$M,$B13) -> 5 | E13: =COUNTIFS(L1L2!$M:$M,$B13,L1L2!$L:$L,$E$1) -> 5 | F13: =IF(AND(H13=1,D13>=2),9,IF(D13>=3,9,0)) -> 9 | G13: =IF(AND(H13=1,E13>=2),3,IF(E13>3,3,E13)) -> 3 | H13: =IF(ISNUMBER(SEARCH("M", C13)), 1, 0) -> 0 | I13: =VLOOKUP(B13,Sheet1!$A:$E,5,FALSE) -> บจก.เจริญภัณฑ์ผลิตคอนกรีต
... A41: 3-West | B41: FC070 | C41: ท่ามะกา | D41: =COUNTIF(L1L2!$M:$M,$B41) -> 4 | E41: =COUNTIFS(L1L2!$M:$M,$B41,L1L2!$L:$L,$E$1) -> 4 | F41: =IF(AND(H41=1,D41>=2),9,IF(D41>=3,9,0)) -> 9 | G41: =IF(AND(H41=1,E41>=2),3,IF(E41>3,3,E41)) -> 3 | H41: =IF(ISNUMBER(SEARCH("M", C41)), 1, 0) -> 0 | I41: =VLOOKUP(B41,Sheet1!$A:$E,5,FALSE) -> บจก.กอวัฒนาคอนกรีต
A42: 3-West | B42: FC254 | C42: พนมทวน | D42: =COUNTIF(L1L2!$M:$M,$B42) -> 3 | E42: =COUNTIFS(L1L2!$M:$M,$B42,L1L2!$L:$L,$E$1) -> 3 | F42: =IF(AND(H42=1,D42>=2),9,IF(D42>=3,9,0)) -> 9 | G42: =IF(AND(H42=1,E42>=2),3,IF(E42>3,3,E42)) -> 3 | H42: =IF(ISNUMBER(SEARCH("M", C42)), 1, 0) -> 0 | I42: =VLOOKUP(B42,Sheet1!$A:$E,5,FALSE) -> บจก.กอวัฒนาคอนกรีต | J42: ท่ามะกา
A43: 3-West | B43: FC369 | C43: FC กาญจนบุรี 2 | D43: =COUNTIF(L1L2!$M:$M,$B43) -> 3 | E43: =COUNTIFS(L1L2!$M:$M,$B43,L1L2!$L:$L,$E$1) -> 3 | F43: =IF(AND(H43=1,D43>=2),9,IF(D43>=3,9,0)) -> 9 | G43: =IF(AND(H43=1,E43>=2),3,IF(E43>3,3,E43)) -> 3 | H43: =IF(ISNUMBER(SEARCH("M", C43)), 1, 0) -> 0 | I43: =VLOOKUP(B43,Sheet1!$A:$E,5,FALSE) -> บจก.กอวัฒนาคอนกรีต
A44: 3-West | B44: FC397 | C44: ท่าม่วง | D44: =COUNTIF(L1L2!$M:$M,$B44) -> 3 | E44: =COUNTIFS(L1L2!$M:$M,$B44,L1L2!$L:$L,$E$1) -> 2 | F44: =IF(AND(H44=1,D44>=2),9,IF(D44>=3,9,0)) -> 9 | G44: =IF(AND(H44=1,E44>=2),3,IF(E44>3,3,E44)) -> 2 | H44: =IF(ISNUMBER(SEARCH("M", C44)), 1, 0) -> 0 | I44: =VLOOKUP(B44,Sheet1!$A:$E,5,FALSE) -> บจก.กอวัฒนาคอนกรีต
A45: 5-NorthEast | B45: FC143 | C45: ธาตุพนม | D45: =COUNTIF(L1L2!$M:$M,$B45) -> 11 | E45: =COUNTIFS(L1L2!$M:$M,$B45,L1L2!$L:$L,$E$1) -> 11 | F45: =IF(AND(H45=1,D45>=2),9,IF(D45>=3,9,0)) -> 9 | G45: =IF(AND(H45=1,E45>=2),3,IF(E45>3,3,E45)) -> 3 | H45: =IF(ISNUMBER(SEARCH("M", C45)), 1, 0) -> 0 | I45: =VLOOKUP(B45,Sheet1!$A:$E,5,FALSE) -> บจก.กิจเจริญชัย ธุรกิจคอนกรีต
A46: 6-South | B46: FC282 | C46: ระนอง | D46: =COUNTIF(L1L2!$M:$M,$B46) -> 4 | E46: =COUNTIFS(L1L2!$M:$M,$B46,L1L2!$L:$L,$E$1) -> 2 | F46: =IF(AND(H46=1,D46>=2),9,IF(D46>=3,9,0)) -> 9 | G46: =IF(AND(H46=1,E46>=2),3,IF(E46>3,3,E46)) -> 2 | H46: =IF(ISNUMBER(SEARCH("M", C46)), 1, 0) -> 0 | I46: =VLOOKUP(B46,Sheet1!$A:$E,5,FALSE) -> บจก.คอนกรีตซีแพคระนอง
A47: 5-NorthEast | B47: 14H5 | C47: อุดร-มิตรภาพ คูย่งฮวด Type N | D47: =COUNTIF(L1L2!$M:$M,$B47) -> 0 | E47: =COUNTIFS(L1L2!$M:$M,$B47,L1L2!$L:$L,$E$1) -> 0 | F47: =IF(AND(H47=1,D47>=2),9,IF(D47>=3,9,0)) -> 0 | G47: =IF(AND(H47=1,E47>=2),3,IF(E47>3,3,E47)) -> 0 | H47: =IF(ISNUMBER(SEARCH("M", C47)), 1, 0) -> 0 | I47: =VLOOKUP(B47,Sheet1!$A:$E,5,FALSE) -> บจก.คูย่งฮวด (1995)
A48: 5-NorthEast | B48: FC090 | C48: สุรินทร์ 1 | D48: =COUNTIF(L1L2!$M:$M,$B48) -> 3 | E48: =COUNTIFS(L1L2!$M:$M,$B48,L1L2!$L:$L,$E$1) -> 3 | F48: =IF(AND(H48=1,D48>=2),9,IF(D48>=3,9,0)) -> 9 | G48: =IF(AND(H48=1,E48>=2),3,IF(E48>3,3,E48)) -> 3 | H48: =IF(ISNUMBER(SEARCH("M", C48)), 1, 0) -> 0 | I48: =VLOOKUP(B48,Sheet1!$A:$E,5,FALSE) -> บจก.คูย่งฮวด (1995)
A49: 5-NorthEast | B49: FC113 | C49: ท่าตูม | D49: =COUNTIF(L1L2!$M:$M,$B49) -> 3 | E49: =COUNTIFS(L1L2!$M:$M,$B49,L1L2!$L:$L,$E$1) -> 3 | F49: =IF(AND(H49=1,D49>=2),9,IF(D49>=3,9,0)) -> 9 | G49: =IF(AND(H49=1,E49>=2),3,IF(E49>3,3,E49)) -> 3 | H49: =IF(ISNUMBER(SEARCH("M", C49)), 1, 0) -> 0 | I49: =VLOOKUP(B49,Sheet1!$A:$E,5,FALSE) -> บจก.คูย่งฮวด (1995)
A50: 5-NorthEast | B50: FC147 | C50: ลำปลายมาศ | D50: =COUNTIF(L1L2!$M:$M,$B50) -> 3 | E50: =COUNTIFS(L1L2!$M:$M,$B50,L1L2!$L:$L,$E$1) -> 3 | F50: =IF(AND(H50=1,D50>=2),9,IF(D50>=3,9,0)) -> 9 | G50: =IF(AND(H50=1,E50>=2),3,IF(E50>3,3,E50)) -> 3 | H50: =IF(ISNUMBER(SEARCH("M", C50)), 1, 0) -> 0 | I50: =VLOOKUP(B50,Sheet1!$A:$E,5,FALSE) -> บจก.คูย่งฮวด (1995)
A51: 5-NorthEast | B51: FC245 | C51: สุรินทร์ 2 | D51: =COUNTIF(L1L2!$M:$M,$B51) -> 3 | E51: =COUNTIFS(L1L2!$M:$M,$B51,L1L2!$L:$L,$E$1) -> 3 | F51: =IF(AND(H51=1,D51>=2),9,IF(D51>=3,9,0)) -> 9 | G51: =IF(AND(H51=1,E51>=2),3,IF(E51>3,3,E51)) -> 3 | H51: =IF(ISNUMBER(SEARCH("M", C51)), 1, 0) -> 0 | I51: =VLOOKUP(B51,Sheet1!$A:$E,5,FALSE) -> บจก.คูย่งฮวด (1995)
A52: 5-NorthEast | B52: FC383 | C52: FC ศีขรภูมิ | D52: =COUNTIF(L1L2!$M:$M,$B52) -> 3 | E52: =COUNTIFS(L1L2!$M:$M,$B52,L1L2!$L:$L,$E$1) -> 3 | F52: =IF(AND(H52=1,D52>=2),9,IF(D52>=3,9,0)) -> 9 | G52: =IF(AND(H52=1,E52>=2),3,IF(E52>3,3,E52)) -> 3 | H52: =IF(ISNUMBER(SEARCH("M", C52)), 1, 0) -> 0 | I52: =VLOOKUP(B52,Sheet1!$A:$E,5,FALSE) -> บจก.คูย่งฮวด (1995)
A53: 5-NorthEast | B53: 31P2 | C53: อุดรธานี Type N | D53: =COUNTIF(L1L2!$M:$M,$B53) -> 5 | E53: =COUNTIFS(L1L2!$M:$M,$B53,L1L2!$L:$L,$E$1) -> 5 | F53: =IF(AND(H53=1,D53>=2),9,IF(D53>=3,9,0)) -> 9 | G53: =IF(AND(H53=1,E53>=2),3,IF(E53>3,3,E53)) -> 3 | H53: =IF(ISNUMBER(SEARCH("M", C53)), 1, 0) -> 0 | I53: =VLOOKUP(B53,Sheet1!$A:$E,5,FALSE) -> บจก.คูย่งฮวด อุดรธานี
A54: 5-NorthEast | B54: FC329 | C54: พยัคฆภูมิพิสัย | D54: =COUNTIF(L1L2!$M:$M,$B54) -> 2 | E54: =COUNTIFS(L1L2!$M:$M,$B54,L1L2!$L:$L,$E$1) -> 2 | F54: =IF(AND(H54=1,D54>=2),9,IF(D54>=3,9,0)) -> 0 | G54: =IF(AND(H54=1,E54>=2),3,IF(E54>3,3,E54)) -> 2 | H54: =IF(ISNUMBER(SEARCH("M", C54)), 1, 0) -> 0 | I54: =VLOOKUP(B54,Sheet1!$A:$E,5,FALSE) -> บจก.จงเจริญ คอนกรีต
... A58: 6-South | B58: FC287 | C58: มาบอำมฤต | D58: =COUNTIF(L1L2!$M:$M,$B58) -> 3 | E58: =COUNTIFS(L1L2!$M:$M,$B58,L1L2!$L:$L,$E$1) -> 3 | F58: =IF(AND(H58=1,D58>=2),9,IF(D58>=3,9,0)) -> 9 | G58: =IF(AND(H58=1,E58>=2),3,IF(E58>3,3,E58)) -> 3 | H58: =IF(ISNUMBER(SEARCH("M", C58)), 1, 0) -> 0 | I58: =VLOOKUP(B58,Sheet1!$A:$E,5,FALSE) -> บจก.ชุมพรไถ่เชียงคอนกรีต
A59: 6-South | B59: 3164 | C59: ปากน้ำชุมพร (N) | D59: =COUNTIF(L1L2!$M:$M,$B59) -> 3 | E59: =COUNTIFS(L1L2!$M:$M,$B59,L1L2!$L:$L,$E$1) -> 3 | F59: =IF(AND(H59=1,D59>=2),9,IF(D59>=3,9,0)) -> 9 | G59: =IF(AND(H59=1,E59>=2),3,IF(E59>3,3,E59)) -> 3 | H59: =IF(ISNUMBER(SEARCH("M", C59)), 1, 0) -> 0 | I59: =VLOOKUP(B59,Sheet1!$A:$E,5,FALSE) -> บจก.ชุมพรไถ่เชียงคอนกรีต
A60: 2-East | B60: 13O5 | C60: ซิโนมา Type X | D60: =COUNTIF(L1L2!$M:$M,$B60) -> 0 | E60: =COUNTIFS(L1L2!$M:$M,$B60,L1L2!$L:$L,$E$1) -> 0 | F60: =IF(AND(H60=1,D60>=2),9,IF(D60>=3,9,0)) -> 0 | G60: =IF(AND(H60=1,E60>=2),3,IF(E60>3,3,E60)) -> 0 | H60: =IF(ISNUMBER(SEARCH("M", C60)), 1, 0) -> 0 | I60: =VLOOKUP(B60,Sheet1!$A:$E,5,FALSE) -> บจก.ซิโนมา หานดาน(ไทยแลนด์)
A61: 3-West | B61: FC176 | C61: บางตะเคียน | D61: =COUNTIF(L1L2!$M:$M,$B61) -> 5 | E61: =COUNTIFS(L1L2!$M:$M,$B61,L1L2!$L:$L,$E$1) -> 3 | F61: =IF(AND(H61=1,D61>=2),9,IF(D61>=3,9,0)) -> 9 | G61: =IF(AND(H61=1,E61>=2),3,IF(E61>3,3,E61)) -> 3 | H61: =IF(ISNUMBER(SEARCH("M", C61)), 1, 0) -> 0 | I61: =VLOOKUP(B61,Sheet1!$A:$E,5,FALSE) -> บจก.ซี.แอล.คอนกรีต
A62: 3-West | B62: FC201 | C62: ศรีประจันต์ | D62: =COUNTIF(L1L2!$M:$M,$B62) -> 5 | E62: =COUNTIFS(L1L2!$M:$M,$B62,L1L2!$L:$L,$E$1) -> 4 | F62: =IF(AND(H62=1,D62>=2),9,IF(D62>=3,9,0)) -> 9 | G62: =IF(AND(H62=1,E62>=2),3,IF(E62>3,3,E62)) -> 3 | H62: =IF(ISNUMBER(SEARCH("M", C62)), 1, 0) -> 0 | I62: =VLOOKUP(B62,Sheet1!$A:$E,5,FALSE) -> บจก.ซี.แอล.คอนกรีต
A63: 3-West | B63: FC214 | C63: ดอนเจดีย์ | D63: =COUNTIF(L1L2!$M:$M,$B63) -> 4 | E63: =COUNTIFS(L1L2!$M:$M,$B63,L1L2!$L:$L,$E$1) -> 4 | F63: =IF(AND(H63=1,D63>=2),9,IF(D63>=3,9,0)) -> 9 | G63: =IF(AND(H63=1,E63>=2),3,IF(E63>3,3,E63)) -> 3 | H63: =IF(ISNUMBER(SEARCH("M", C63)), 1, 0) -> 0 | I63: =VLOOKUP(B63,Sheet1!$A:$E,5,FALSE) -> บจก.ซี.แอล.คอนกรีต
A64: 3-West | B64: FC248 | C64: สองพี่น้อง | D64: =COUNTIF(L1L2!$M:$M,$B64) -> 4 | E64: =COUNTIFS(L1L2!$M:$M,$B64,L1L2!$L:$L,$E$1) -> 4 | F64: =IF(AND(H64=1,D64>=2),9,IF(D64>=3,9,0)) -> 9 | G64: =IF(AND(H64=1,E64>=2),3,IF(E64>3,3,E64)) -> 3 | H64: =IF(ISNUMBER(SEARCH("M", C64)), 1, 0) -> 0 | I64: =VLOOKUP(B64,Sheet1!$A:$E,5,FALSE) -> บจก.ซี.แอล.คอนกรีต
A65: 3-West | B65: FC299 | C65: สองพี่น้อง 2 | D65: =COUNTIF(L1L2!$M:$M,$B65) -> 3 | E65: =COUNTIFS(L1L2!$M:$M,$B65,L1L2!$L:$L,$E$1) -> 3 | F65: =IF(AND(H65=1,D65>=2),9,IF(D65>=3,9,0)) -> 9 | G65: =IF(AND(H65=1,E65>=2),3,IF(E65>3,3,E65)) -> 3 | H65: =IF(ISNUMBER(SEARCH("M", C65)), 1, 0) -> 0 | I65: =VLOOKUP(B65,Sheet1!$A:$E,5,FALSE) -> บจก.ซี.แอล.คอนกรีต
A66: 5-NorthEast | B66: FC242 | C66: ภูเรือ | D66: =COUNTIF(L1L2!$M:$M,$B66) -> 3 | E66: =COUNTIFS(L1L2!$M:$M,$B66,L1L2!$L:$L,$E$1) -> 3 | F66: =IF(AND(H66=1,D66>=2),9,IF(D66>=3,9,0)) -> 9 | G66: =IF(AND(H66=1,E66>=2),3,IF(E66>3,3,E66)) -> 3 | H66: =IF(ISNUMBER(SEARCH("M", C66)), 1, 0) -> 0 | I66: =VLOOKUP(B66,Sheet1!$A:$E,5,FALSE) -> บจก.ซี.ซี.คอนกรีต
A67: 5-NorthEast | B67: FC337 | C67: M เชียงคาน | D67: =COUNTIF(L1L2!$M:$M,$B67) -> 2 | E67: =COUNTIFS(L1L2!$M:$M,$B67,L1L2!$L:$L,$E$1) -> 2 | F67: =IF(AND(H67=1,D67>=2),9,IF(D67>=3,9,0)) -> 9 | G67: =IF(AND(H67=1,E67>=2),3,IF(E67>3,3,E67)) -> 3 | H67: =IF(ISNUMBER(SEARCH("M", C67)), 1, 0) -> 1 | I67: =VLOOKUP(B67,Sheet1!$A:$E,5,FALSE) -> บจก.ซี.ซี.คอนกรีต
A68: 5-NorthEast | B68: ZZP6 | C68: เมืองเลย 2 Type N | D68: =COUNTIF(L1L2!$M:$M,$B68) -> 4 | E68: =COUNTIFS(L1L2!$M:$M,$B68,L1L2!$L:$L,$E$1) -> 4 | F68: =IF(AND(H68=1,D68>=2),9,IF(D68>=3,9,0)) -> 9 | G68: =IF(AND(H68=1,E68>=2),3,IF(E68>3,3,E68)) -> 3 | H68: =IF(ISNUMBER(SEARCH("M", C68)), 1, 0) -> 0 | I68: =VLOOKUP(B68,Sheet1!$A:$E,5,FALSE) -> บจก.ซี.ซี.คอนกรีต
A69: 4-North | B69: FC194 | C69: พาน | D69: =COUNTIF(L1L2!$M:$M,$B69) -> 4 | E69: =COUNTIFS(L1L2!$M:$M,$B69,L1L2!$L:$L,$E$1) -> 4 | F69: =IF(AND(H69=1,D69>=2),9,IF(D69>=3,9,0)) -> 9 | G69: =IF(AND(H69=1,E69>=2),3,IF(E69>3,3,E69)) -> 3 | H69: =IF(ISNUMBER(SEARCH("M", C69)), 1, 0) -> 0 | I69: =VLOOKUP(B69,Sheet1!$A:$E,5,FALSE) -> บจก.ซีแมทคอนกรีต
A70: 4-North | B70: FC195 | C70: เวียงป่าเป้า | D70: =COUNTIF(L1L2!$M:$M,$B70) -> 3 | E70: =COUNTIFS(L1L2!$M:$M,$B70,L1L2!$L:$L,$E$1) -> 3 | F70: =IF(AND(H70=1,D70>=2),9,IF(D70>=3,9,0)) -> 9 | G70: =IF(AND(H70=1,E70>=2),3,IF(E70>3,3,E70)) -> 3 | H70: =IF(ISNUMBER(SEARCH("M", C70)), 1, 0) -> 0 | I70: =VLOOKUP(B70,Sheet1!$A:$E,5,FALSE) -> บจก.ซีแมทคอนกรีต
...

Sheet Sheet1
A1: รหัส | B1: ชื่อโรงงาน | C1: กิจการ | D1: รหัส | E1: หจก./บจก.
A2: 31ED | B2: หลวงแพ่ง | C2: 1-Metro | D2: FR109 | E2: บจก.เจเอ็นเจพี ซิเมนต์ | F2: =VLOOKUP(A2,Score!B:B,1,FALSE) -> 31ED
A3: 31EC | B3: คลองด่าน | C3: 1-Metro | D3: FR100 | E3: บจก.เอส.เอส.พี (072) คอนสตรัคชั่น | F3: =VLOOKUP(A3,Score!B:B,1,FALSE) -> 31EC
A4: 31EF | B4: นพวงศ์ | C4: 1-Metro | D4: FR187 | E4: หจก.เพาเวอร์ แลนด์ คอนกรีต | F4: =VLOOKUP(A4,Score!B:B,1,FALSE) -> 31EF
A5: FC139 | B5: คลอง 11 | C5: 1-Metro | D5: FR002 | E5: บจก.สหชัยธุรกิจก่อสร้าง 1993 | F5: =VLOOKUP(A5,Score!B:B,1,FALSE) -> FC139
A6: FC095 | B6: มวกเหล็ก | C6: 2-East | D6: FR002 | E6: บจก.สหชัยธุรกิจก่อสร้าง 1993 | F6: =VLOOKUP(A6,Score!B:B,1,FALSE) -> FC095
A7: FC046 | B7: วังม่วง | C7: 2-East | D7: FR002 | E7: บจก.สหชัยธุรกิจก่อสร้าง 1993 | F7: =VLOOKUP(A7,Score!B:B,1,FALSE) -> FC046
A8: FC175 | B8: พัฒนานิคม | C8: 2-East | D8: FR002 | E8: บจก.สหชัยธุรกิจก่อสร้าง 1993 | F8: =VLOOKUP(A8,Score!B:B,1,FALSE) -> FC175
A9: FC390 | B9: โคกสำโรง | C9: 2-East | D9: FR002 | E9: บจก.สหชัยธุรกิจก่อสร้าง 1993 | F9: =VLOOKUP(A9,Score!B:B,1,FALSE) -> FC390
A10: FC013 | B10: ลำนารายณ์ | C10: 2-East | D10: FR005 | E10: บจก.นิธิศพันธ์ | F10: =VLOOKUP(A10,Score!B:B,1,FALSE) -> FC013
A11: FC111 | B11: ดาวเรือง 1 | C11: 2-East | D11: FR003 | E11: บจก.ศุภภัณฑ์คอนกรีต | F11: =VLOOKUP(A11,Score!B:B,1,FALSE) -> FC111
A12: FC209 | B12: บ้านหมอ | C12: 2-East | D12: FR150 | E12: หจก.ดวงแสงทองคอนกรีต | F12: =VLOOKUP(A12,Score!B:B,1,FALSE) -> FC209
A13: FC389 | B13: บ้านหมอ 2 | C13: 2-East | D13: FR150 | E13: หจก.ดวงแสงทองคอนกรีต | F13: =VLOOKUP(A13,Score!B:B,1,FALSE) -> FC389
... A253: FC029 | B253: ไชยา | C253: 6-South | D253: FR053 | E253: บจก.ไชยาคอนกรีต | F253: =VLOOKUP(A253,Score!B:B,1,FALSE) -> FC029
A254: 3164 | B254: ปากน้ำชุมพร | C254: 6-South | D254: FR159 | E254: บจก.ชุมพรไถ่เชียงคอนกรีต | F254: =VLOOKUP(A254,Score!B:B,1,FALSE) -> 3164
A255: FC287 | B255: มาบอำมฤต | C255: 6-South | D255: FR159 | E255: บจก.ชุมพรไถ่เชียงคอนกรีต | F255: =VLOOKUP(A255,Score!B:B,1,FALSE) -> FC287
A256: FC282 | B256: ระนอง | C256: 6-South | D256: FR211 | E256: บจก.คอนกรีตซีแพคระนอง | F256: =VLOOKUP(A256,Score!B:B,1,FALSE) -> FC282
A257: 3165 | B257: ผาหลวงคอนกรีต 1 | C257: 6-South | D257: FR162 | E257: บจก.ผาหลวงคอนกรีต | F257: =VLOOKUP(A257,Score!B:B,1,FALSE) -> 3165
A258: 3166 | B258: ผาหลวงคอนกรีต 2 | C258: 6-South | D258: FR162 | E258: บจก.ผาหลวงคอนกรีต | F258: =VLOOKUP(A258,Score!B:B,1,FALSE) -> 3166
A259: FC115 | B259: เกาะพะงัน | C259: 6-South | D259: FR073 | E259: หจก.ลิ้มปิพงษ์ค้าวัสดุก่อสร้างและคอนกรีต | F259: =VLOOKUP(A259,Score!B:B,1,FALSE) -> FC115
A260: 3168 | B260: หนองขรี | C260: 6-South | D260: FR202 | E260: บจก.พุนพินมาตรฐานคอนกรีต | F260: =VLOOKUP(A260,Score!B:B,1,FALSE) -> 3168
A261: FC253 | B261: นาสาร | C261: 6-South | D261: FR093 | E261: บจก.ปัญญามาตรฐานคอนกรีต | F261: =VLOOKUP(A261,Score!B:B,1,FALSE) -> FC253
A262: FC129 | B262: ทุ่งใหญ่ | C262: 6-South | D262: FR093 | E262: บจก.ปัญญามาตรฐานคอนกรีต | F262: =VLOOKUP(A262,Score!B:B,1,FALSE) -> FC129
A263: FC295 | B263: บางสวรรค์ 3 | C263: 6-South | D263: FR093 | E263: บจก.ปัญญามาตรฐานคอนกรีต | F263: =VLOOKUP(A263,Score!B:B,1,FALSE) -> FC295
A264: FC356 | B264: นาสาร 2 | C264: 6-South | D264: FR093 | E264: บจก.ปัญญามาตรฐานคอนกรีต | F264: =VLOOKUP(A264,Score!B:B,1,FALSE) -> FC356
A265: FC396 | B265: เวียงสระ | C265: 6-South | D265: FR093 | E265: บจก.ปัญญามาตรฐานคอนกรีต | F265: =VLOOKUP(A265,Score!B:B,1,FALSE) -> FC396
A266: FC006 | B266: ขนอม | C266: 6-South | D266: FR055 | E266: หจก.ขนอมคอนกรีต 2000 | F266: =VLOOKUP(A266,Score!B:B,1,FALSE) -> FC006
... A291: FC413 | B291: เขาหลักโกลเด้นฮิลล์ | C291: 6-South | D291: FR097 | E291: หจก.วี.วี.เอ็มคอนกรีต | F291: =VLOOKUP(A291,Score!B:B,1,FALSE) -> FC413

Sheet ข้อมูลกิจการ
B1: FCPLNO | C1: NAMET | D1: DEPTNAMET
A2: =B2&" "&":"&" "&C2 -> FC139 : คลอง 11 | B2: FC139 | C2: คลอง 11 | D2: กรุงเทพ
A3: =B3&" "&":"&" "&C3 -> FC092 : อู่ทอง | B3: FC092 | C3: อู่ทอง | D3: ตะวันตก
A4: =B4&" "&":"&" "&C4 -> FC236 : ทับสะแก | B4: FC236 | C4: ทับสะแก | D4: ตะวันตก
A5: =B5&" "&":"&" "&C5 -> FC158 : แก่งกระจาน | B5: FC158 | C5: แก่งกระจาน | D5: ตะวันตก
A6: =B6&" "&":"&" "&C6 -> FC142 : บางปลาม้า | B6: FC142 | C6: บางปลาม้า | D6: ตะวันตก
A7: =B7&" "&":"&" "&C7 -> FC176 : บางตะเคียน | B7: FC176 | C7: บางตะเคียน | D7: ตะวันตก
A8: =B8&" "&":"&" "&C8 -> FC197 : สรรคบุรี | B8: FC197 | C8: สรรคบุรี | D8: ตะวันตก
A9: =B9&" "&":"&" "&C9 -> FC070 : ท่ามะกา | B9: FC070 | C9: ท่ามะกา | D9: ตะวันตก
A10: =B10&" "&":"&" "&C10 -> FC009 : ประจวบคีรีขันธ์ | B10: FC009 | C10: ประจวบคีรีขันธ์ | D10: ตะวันตก
A11: =B11&" "&":"&" "&C11 -> FC137 : ห้วยมงคล | B11: FC137 | C11: ห้วยมงคล | D11: ตะวันตก
A12: =B12&" "&":"&" "&C12 -> FC035 : บางสะพาน | B12: FC035 | C12: บางสะพาน | D12: ตะวันตก
A13: =B13&" "&":"&" "&C13 -> FC069 : จอมบึง | B13: FC069 | C13: จอมบึง | D13: ตะวันตก
... A276: =B276&" "&":"&" "&C276 -> 3167 : FC เจ้าฟ้าภูเก็ต | B276: 3167 | C276: FC เจ้าฟ้าภูเก็ต | D276: ใต้
